Workbook

Sheet Selection Sheet
B4: Project | C4: {Project}
B5: Client: | C5: {Customer}
B7: Contractor:
D8: Match | E8: Tkw
F9: TRUE | G9: FALSE
D10: Variation | E10: 0 | F10: 0 | G10: 0
B12: SPECIFIED | H12: PROPOSED
B13: Ref | C13: Type | D13: Location | E13: TKw | F13: SKw | G13: L/S | H13: Model ( Indoor / Outdoor ) | I13: Qty | J13: NOMINAL TR | K13: Type | L13: Refrigerant | M13: Temperature | O13: Capacity (KW) | Q13: AFR | R13: SPEED | S13: Power Input, KW | U13: COP | V13: ESP | W13: Power Supply | X13: Dimensions | AA13: Dimensions | AD13: Weight | AG13: DO NOT DELETE/TAMPER WITH THESE COLUMNS
M14: degC | O14: TC | P14: SC | Q14: L/S | S14: Actual | T14: ESMA | X14: Indoor, mm | AA14: Outdoor, mm | AD14: Indoor | AE14: Outdoor
M15: Indoor | N15: Outdoor | U15: W/W | X15: H | Y15: W | Z15: D | AA15: H | AB15: W | AC15: D | AD15: kg | AE15: kg | AG15: TKW | AH15: SKW | AI15: L/S | AJ15: Ind TKw | AK15: Ind SKw | AL15: Ind L/S | AM15: Max Ind | AN15: Final Selection | AO15: Qty
H16: Model | I16: Qty
H17: =AN17 | I17: =AO17 | J17: =IF($H17="","",VLOOKUP($H17,Data!$C$6:$Y$29,2,FALSE)) | K17: =IF($H17="","",VLOOKUP($H17,Data!$C$6:$Y$29,3,FALSE)) | L17: =IF($H17="","",VLOOKUP($H17,Data!$C$6:$Y$29,4,FALSE)) | M17: =IF($H17="","",VLOOKUP($H17,Data!$C$6:$Y$29,5,FALSE)) | N17: =IF($H17="","",VLOOKUP($H17,Data!$C$6:$Y$29,6,FALSE)) | O17: =IF($H17="","",VLOOKUP($H17,Data!$C$6:$Y$29,7,FALSE)) | P17: =IF($H17="","",VLOOKUP($H17,Data!$C$6:$Y$29,8,FALSE)) | Q17: =IF($H17="","",VLOOKUP($H17,Data!$C$6:$Y$29,9,FALSE)) | R17: =IF($H17="","",VLOOKUP($H17,Data!$C$6:$Y$29,10,FALSE)) | S17: =IF($H17="","",VLOOKUP($H17,Data!$C$6:$Y$29,11,FALSE)) | T17: =IF($H17="","",VLOOKUP($H17,Data!$C$6:$Y$29,12,FALSE)) | U17: =IF($H17="","",VLOOKUP($H17,Data!$C$6:$Y$29,13,FALSE)) | V17: =IF($H17="","",VLOOKUP($H17,Data!$C$6:$Y$29,14,FALSE)) | W17: =IF($H17="","",VLOOKUP($H17,Data!$C$6:$Y$29,15,FALSE)) | X17: =IF($H17="","",VLOOKUP($H17,Data!$C$6:$Y$29,16,FALSE)) | Y17: =IF($H17="","",VLOOKUP($H17,Data!$C$6:$Y$29,17,FALSE)) | Z17: =IF($H17="","",VLOOKUP($H17,Data!$C$6:$Y$29,18,FALSE)) | AA17: =IF($H17="","",VLOOKUP($H17,Data!$C$6:$Y$29,19,FALSE)) | AB17: =IF($H17="","",VLOOKUP($H17,Data!$C$6:$Y$29,20,FALSE)) | AC17: =IF($H17="","",VLOOKUP($H17,Data!$C$6:$Y$29,21,FALSE)) | AD17: =IF($H17="","",VLOOKUP($H17,Data!$C$6:$Y$29,22,FALSE)) | AE17: =IF($H17="","",VLOOKUP($H17,Data!$C$6:$Y$29,23,FALSE)) | AG17: =IF($E17="","",IF($C17="DUCTED",VLOOKUP($E17,'DX-Data'!$D$5:$J$11,7,TRUE),IF($C17="DECORATIVE",VLOOKUP($E17,'DX-Data'!$D$19:$J$23,7,TRUE),IF($C17="PACKAGED",VLOOKUP($E17,'DX-Data'!$D$24:$J$30,7,TRUE),IF($C17="DUCTED-INV",VLOOKUP($E17,'DX-Data'!$D$12:$J$18,7,TRUE),"CHOOSE AC TYPE"))))) | AH17: =IF($F$9=TRUE,IF($C17="DUCTED",VLOOKUP($F17,'DX-Data'!$F$5:$J$11,5,TRUE),IF($C17="DECORATIVE",VLOOKUP($F17,'DX-Data'!$F$19:$J$23,5,TRUE),IF($C17="PACKAGED",VLOOKUP($F17,'DX-Data'!$F$24:$J$30,5,TRUE),IF($C17="DUCTED-INV",VLOOKUP($F17,'DX-Data'!$F$12:$J$18,5,TRUE),"CHOOSE AC TYPE")))),"NO SELECTION") -> CHOOSE AC TYPE | AI17: =IF($G$9=TRUE,IF($C17="DUCTED",VLOOKUP($G17,'DX-Data'!$H$5:$J$11,3,TRUE),IF($C17="DECORATIVE",VLOOKUP($G17,'DX-Data'!$H$19:$J$23,3,TRUE),IF($C17="PACKAGED",VLOOKUP($G17,'DX-Data'!$H$24:$J$30,3,TRUE),IF($C17="DUCTED-INV",VLOOKUP($G17,'DX-Data'!$H$12:$J$18,3,TRUE),"CHOOSE AC TYPE")))),"NO SELECTION") -> NO SELECTION | AJ17: =IF($E17="","",IF($C17="DUCTED",VLOOKUP($E17,'DX-Data'!$D$5:$J$11,6,TRUE),IF($C17="DECORATIVE",VLOOKUP($E17,'DX-Data'!$D$19:$J$23,6,TRUE),IF($C17="PACKAGED",VLOOKUP($E17,'DX-Data'!$D$24:$J$30,6,TRUE),IF($C17="DUCTED-INV",VLOOKUP($E17,'DX-Data'!$D$12:$J$18,6,TRUE),0))))) | AK17: =IF($F$9=TRUE,IF($C17="DUCTED",VLOOKUP($F17,'DX-Data'!$F$5:$J$11,4,TRUE),IF($C17="DECORATIVE",VLOOKUP($F17,'DX-Data'!$F$19:$J$23,4,TRUE),IF($C17="PACKAGED",VLOOKUP($F17,'DX-Data'!$F$24:$J$30,4,TRUE),IF($C17="DUCTED-INV",VLOOKUP($F17,'DX-Data'!$F$12:$J$18,4,TRUE),"CHOOSE AC TYPE")))),0) -> CHOOSE AC TYPE | AL17: =IF($G$9=TRUE,IF($C17="DUCTED",VLOOKUP($G17,'DX-Data'!$H$5:$J$11,2,TRUE),IF($C17="DECORATIVE",VLOOKUP($G17,'DX-Data'!$H$19:$J$23,2,TRUE),IF($C17="PACKAGED",VLOOKUP($G17,'DX-Data'!$H$24:$J$30,2,TRUE),IF($C17="DUCTED-INV",VLOOKUP($G17,'DX-Data'!$H$12:$J$18,2,TRUE),"CHOOSE AC TYPE")))),0) -> 0 | AM17: =MAX(AJ17:AL17) -> 0 | AN17: =IF(E17="","",VLOOKUP($AM17,'DX-Data'!$I$5:$J$31,2,FALSE)) | AO17: =IF(OR(AN17="",AN17=0),"",1)
B18: UG-DS-01 | C18: DUCTED | D18: PUMP ROOM | E18: 2.2 | F18: 1.9 | G18: 154 | H18: =AN18 -> FDMRN20AVKU - RR20AVKU | I18: =AO18 -> 1 | J18: =IF($H18="","",VLOOKUP($H18,Data!$C$6:$Y$29,2,FALSE)) -> 1.5 | K18: =IF($H18="","",VLOOKUP($H18,Data!$C$6:$Y$29,3,FALSE)) -> Non-Inverter | L18: =IF($H18="","",VLOOKUP($H18,Data!$C$6:$Y$29,4,FALSE)) -> R-410A | M18: =IF($H18="","",VLOOKUP($H18,Data!$C$6:$Y$29,5,FALSE)) -> 24/16 | N18: =IF($H18="","",VLOOKUP($H18,Data!$C$6:$Y$29,6,FALSE)) -> 46 | O18: =IF($H18="","",VLOOKUP($H18,Data!$C$6:$Y$29,7,FALSE)) -> 4.24 | P18: =IF($H18="","",VLOOKUP($H18,Data!$C$6:$Y$29,8,FALSE)) -> 4.11 | Q18: =IF($H18="","",VLOOKUP($H18,Data!$C$6:$Y$29,9,FALSE)) -> 255 | R18: =IF($H18="","",VLOOKUP($H18,Data!$C$6:$Y$29,10,FALSE)) -> MEDIUM | S18: =IF($H18="","",VLOOKUP($H18,Data!$C$6:$Y$29,11,FALSE)) -> 1.77 | T18: =IF($H18="","",VLOOKUP($H18,Data!$C$6:$Y$29,12,FALSE)) -> 1.8 | U18: =IF($H18="","",VLOOKUP($H18,Data!$C$6:$Y$29,13,FALSE)) -> 3.49 | V18: =IF($H18="","",VLOOKUP($H18,Data!$C$6:$Y$29,14,FALSE)) -> 40 | W18: =IF($H18="","",VLOOKUP($H18,Data!$C$6:$Y$29,15,FALSE)) -> 220-240/1/50 | X18: =IF($H18="","",VLOOKUP($H18,Data!$C$6:$Y$29,16,FALSE)) -> 261 | Y18: =IF($H18="","",VLOOKUP($H18,Data!$C$6:$Y$29,17,FALSE)) -> 1200 | Z18: =IF($H18="","",VLOOKUP($H18,Data!$C$6:$Y$29,18,FALSE)) -> 448 | AA18: =IF($H18="","",VLOOKUP($H18,Data!$C$6:$Y$29,19,FALSE)) -> 753 | AB18: =IF($H18="","",VLOOKUP($H18,Data!$C$6:$Y$29,20,FALSE)) -> 855 | AC18: =IF($H18="","",VLOOKUP($H18,Data!$C$6:$Y$29,21,FALSE)) -> 328 | AD18: =IF($H18="","",VLOOKUP($H18,Data!$C$6:$Y$29,22,FALSE)) -> 26 | AE18: =IF($H18="","",VLOOKUP($H18,Data!$C$6:$Y$29,23,FALSE)) -> 47 | AG18: =IF($E18="","",IF($C18="DUCTED",VLOOKUP($E18,'DX-Data'!$D$5:$J$11,7,TRUE),IF($C18="DECORATIVE",VLOOKUP($E18,'DX-Data'!$D$19:$J$23,7,TRUE),IF($C18="PACKAGED",VLOOKUP($E18,'DX-Data'!$D$24:$J$30,7,TRUE),IF($C18="DUCTED-INV",VLOOKUP($E18,'DX-Data'!$D$12:$J$18,7,TRUE),"CHOOSE AC TYPE"))))) -> FDMRN20AVKU - RR20AVKU | AH18: =IF($F$9=TRUE,IF($C18="DUCTED",VLOOKUP($F18,'DX-Data'!$F$5:$J$11,5,TRUE),IF($C18="DECORATIVE",VLOOKUP($F18,'DX-Data'!$F$19:$J$23,5,TRUE),IF($C18="PACKAGED",VLOOKUP($F18,'DX-Data'!$F$24:$J$30,5,TRUE),IF($C18="DUCTED-INV",VLOOKUP($F18,'DX-Data'!$F$12:$J$18,5,TRUE),"CHOOSE AC TYPE")))),"NO SELECTION") -> FDMRN20AVKU - RR20AVKU | AI18: =IF($G$9=TRUE,IF($C18="DUCTED",VLOOKUP($G18,'DX-Data'!$H$5:$J$11,3,TRUE),IF($C18="DECORATIVE",VLOOKUP($G18,'DX-Data'!$H$19:$J$23,3,TRUE),IF($C18="PACKAGED",VLOOKUP($G18,'DX-Data'!$H$24:$J$30,3,TRUE),IF($C18="DUCTED-INV",VLOOKUP($G18,'DX-Data'!$H$12:$J$18,3,TRUE),"CHOOSE AC TYPE")))),"NO SELECTION") -> NO SELECTION | AJ18: =IF($E18="","",IF($C18="DUCTED",VLOOKUP($E18,'DX-Data'!$D$5:$J$11,6,TRUE),IF($C18="DECORATIVE",VLOOKUP($E18,'DX-Data'!$D$19:$J$23,6,TRUE),IF($C18="PACKAGED",VLOOKUP($E18,'DX-Data'!$D$24:$J$30,6,TRUE),IF($C18="DUCTED-INV",VLOOKUP($E18,'DX-Data'!$D$12:$J$18,6,TRUE),0))))) -> 1 | AK18: =IF($F$9=TRUE,IF($C18="DUCTED",VLOOKUP($F18,'DX-Data'!$F$5:$J$11,4,TRUE),IF($C18="DECORATIVE",VLOOKUP($F18,'DX-Data'!$F$19:$J$23,4,TRUE),IF($C18="PACKAGED",VLOOKUP($F18,'DX-Data'!$F$24:$J$30,4,TRUE),IF($C18="DUCTED-INV",VLOOKUP($F18,'DX-Data'!$F$12:$J$18,4,TRUE),"CHOOSE AC TYPE")))),0) -> 1 | AL18: =IF($G$9=TRUE,IF($C18="DUCTED",VLOOKUP($G18,'DX-Data'!$H$5:$J$11,2,TRUE),IF($C18="DECORATIVE",VLOOKUP($G18,'DX-Data'!$H$19:$J$23,2,TRUE),IF($C18="PACKAGED",VLOOKUP($G18,'DX-Data'!$H$24:$J$30,2,TRUE),IF($C18="DUCTED-INV",VLOOKUP($G18,'DX-Data'!$H$12:$J$18,2,TRUE),"CHOOSE AC TYPE")))),0) -> 0 | AM18: =MAX(AJ18:AL18) -> 1 | AN18: =IF(E18="","",VLOOKUP($AM18,'DX-Data'!$I$5:$J$31,2,FALSE)) -> FDMRN20AVKU - RR20AVKU | AO18: =IF(OR(AN18="",AN18=0),"",1) -> 1
B20: GF-DS-01 | C20: DUCTED | D20: MAIN ENTRANCE | E20: 12.3 | F20: 9.9 | G20: 856 | H20: FDMRN30AVKU - RR30AVKU | I20: 2 | J20: =IF($H20="","",VLOOKUP($H20,Data!$C$6:$Y$29,2,FALSE)) -> 2.5 | K20: =IF($H20="","",VLOOKUP($H20,Data!$C$6:$Y$29,3,FALSE)) -> Non-Inverter | L20: =IF($H20="","",VLOOKUP($H20,Data!$C$6:$Y$29,4,FALSE)) -> R-410A | M20: =IF($H20="","",VLOOKUP($H20,Data!$C$6:$Y$29,5,FALSE)) -> 24/16 | N20: =IF($H20="","",VLOOKUP($H20,Data!$C$6:$Y$29,6,FALSE)) -> 46 | O20: =IF($H20="","",VLOOKUP($H20,Data!$C$6:$Y$29,7,FALSE)) -> 6.93 | P20: =IF($H20="","",VLOOKUP($H20,Data!$C$6:$Y$29,8,FALSE)) -> 6.3 | Q20: =IF($H20="","",VLOOKUP($H20,Data!$C$6:$Y$29,9,FALSE)) -> 374 | R20: =IF($H20="","",VLOOKUP($H20,Data!$C$6:$Y$29,10,FALSE)) -> MEDIUM | S20: =IF($H20="","",VLOOKUP($H20,Data!$C$6:$Y$29,11,FALSE)) -> 2.87 | T20: =IF($H20="","",VLOOKUP($H20,Data!$C$6:$Y$29,12,FALSE)) -> 3.05 | U20: =IF($H20="","",VLOOKUP($H20,Data!$C$6:$Y$29,13,FALSE)) -> 3.49 | V20: =IF($H20="","",VLOOKUP($H20,Data!$C$6:$Y$29,14,FALSE)) -> 40 | W20: =IF($H20="","",VLOOKUP($H20,Data!$C$6:$Y$29,15,FALSE)) -> 220-240/1/50 | X20: =IF($H20="","",VLOOKUP($H20,Data!$C$6:$Y$29,16,FALSE)) -> 378 | Y20: =IF($H20="","",VLOOKUP($H20,Data!$C$6:$Y$29,17,FALSE)) -> 1115 | Z20: =IF($H20="","",VLOOKUP($H20,Data!$C$6:$Y$29,18,FALSE)) -> 541 | AA20: =IF($H20="","",VLOOKUP($H20,Data!$C$6:$Y$29,19,FALSE)) -> 852 | AB20: =IF($H20="","",VLOOKUP($H20,Data!$C$6:$Y$29,20,FALSE)) -> 1030 | AC20: =IF($H20="","",VLOOKUP($H20,Data!$C$6:$Y$29,21,FALSE)) -> 400 | AD20: =IF($H20="","",VLOOKUP($H20,Data!$C$6:$Y$29,22,FALSE)) -> 44 | AE20: =IF($H20="","",VLOOKUP($H20,Data!$C$6:$Y$29,23,FALSE)) -> 75 | AG20: =IF($E20="","",IF($C20="DUCTED",VLOOKUP($E20,'DX-Data'!$D$5:$J$11,7,TRUE),IF($C20="DECORATIVE",VLOOKUP($E20,'DX-Data'!$D$19:$J$23,7,TRUE),IF($C20="PACKAGED",VLOOKUP($E20,'DX-Data'!$D$24:$J$30,7,TRUE),IF($C20="DUCTED-INV",VLOOKUP($E20,'DX-Data'!$D$12:$J$18,7,TRUE),"CHOOSE AC TYPE"))))) -> FDMRN60AVKU - RR60AYKU | AH20: =IF($F$9=TRUE,IF($C20="DUCTED",VLOOKUP($F20,'DX-Data'!$F$5:$J$11,5,TRUE),IF($C20="DECORATIVE",VLOOKUP($F20,'DX-Data'!$F$19:$J$23,5,TRUE),IF($C20="PACKAGED",VLOOKUP($F20,'DX-Data'!$F$24:$J$30,5,TRUE),IF($C20="DUCTED-INV",VLOOKUP($F20,'DX-Data'!$F$12:$J$18,5,TRUE),"CHOOSE AC TYPE")))),"NO SELECTION") -> FDMRN50AVKU - RR50AYKU | AI20: =IF($G$9=TRUE,IF($C20="DUCTED",VLOOKUP($G20,'DX-Data'!$H$5:$J$11,3,TRUE),IF($C20="DECORATIVE",VLOOKUP($G20,'DX-Data'!$H$19:$J$23,3,TRUE),IF($C20="PACKAGED",VLOOKUP($G20,'DX-Data'!$H$24:$J$30,3,TRUE),IF($C20="DUCTED-INV",VLOOKUP($G20,'DX-Data'!$H$12:$J$18,3,TRUE),"CHOOSE AC TYPE")))),"NO SELECTION") -> NO SELECTION | AJ20: =IF($E20="","",IF($C20="DUCTED",VLOOKUP($E20,'DX-Data'!$D$5:$J$11,6,TRUE),IF($C20="DECORATIVE",VLOOKUP($E20,'DX-Data'!$D$19:$J$23,6,TRUE),IF($C20="PACKAGED",VLOOKUP($E20,'DX-Data'!$D$24:$J$30,6,TRUE),IF($C20="DUCTED-INV",VLOOKUP($E20,'DX-Data'!$D$12:$J$18,6,TRUE),0))))) -> 6 | AK20: =IF($F$9=TRUE,IF($C20="DUCTED",VLOOKUP($F20,'DX-Data'!$F$5:$J$11,4,TRUE),IF($C20="DECORATIVE",VLOOKUP($F20,'DX-Data'!$F$19:$J$23,4,TRUE),IF($C20="PACKAGED",VLOOKUP($F20,'DX-Data'!$F$24:$J$30,4,TRUE),IF($C20="DUCTED-INV",VLOOKUP($F20,'DX-Data'!$F$12:$J$18,4,TRUE),"CHOOSE AC TYPE")))),0) -> 5 | AL20: =IF($G$9=TRUE,IF($C20="DUCTED",VLOOKUP($G20,'DX-Data'!$H$5:$J$11,2,TRUE),IF($C20="DECORATIVE",VLOOKUP($G20,'DX-Data'!$H$19:$J$23,2,TRUE),IF($C20="PACKAGED",VLOOKUP($G20,'DX-Data'!$H$24:$J$30,2,TRUE),IF($C20="DUCTED-INV",VLOOKUP($G20,'DX-Data'!$H$12:$J$18,2,TRUE),"CHOOSE AC TYPE")))),0) -> 0 | AM20: =MAX(AJ20:AL20) -> 6 | AN20: =IF(E20="","",VLOOKUP($AM20,'DX-Data'!$I$5:$J$31,2,FALSE)) -> FDMRN60AVKU - RR60AYKU | AO20: =IF(OR(AN20="",AN20=0),"",1) -> 1
B21: GF-DS-02 | C21: DUCTED | D21: LV ROOM | E21: 4.4 | F21: 4 | G21: 354 | H21: =AN21 -> FDMRN25AVKU - RR25AVKU | I21: =AO21 -> 1 | J21: =IF($H21="","",VLOOKUP($H21,Data!$C$6:$Y$29,2,FALSE)) -> 2 | K21: =IF($H21="","",VLOOKUP($H21,Data!$C$6:$Y$29,3,FALSE)) -> Non-Inverter | L21: =IF($H21="","",VLOOKUP($H21,Data!$C$6:$Y$29,4,FALSE)) -> R-410A | M21: =IF($H21="","",VLOOKUP($H21,Data!$C$6:$Y$29,5,FALSE)) -> 24/16 | N21: =IF($H21="","",VLOOKUP($H21,Data!$C$6:$Y$29,6,FALSE)) -> 46 | O21: =IF($H21="","",VLOOKUP($H21,Data!$C$6:$Y$29,7,FALSE)) -> 5.48 | P21: =IF($H21="","",VLOOKUP($H21,Data!$C$6:$Y$29,8,FALSE)) -> 5.05 | Q21: =IF($H21="","",VLOOKUP($H21,Data!$C$6:$Y$29,9,FALSE)) -> 303 | R21: =IF($H21="","",VLOOKUP($H21,Data!$C$6:$Y$29,10,FALSE)) -> MEDIUM | S21: =IF($H21="","",VLOOKUP($H21,Data!$C$6:$Y$29,11,FALSE)) -> 2.29 | T21: =IF($H21="","",VLOOKUP($H21,Data!$C$6:$Y$29,12,FALSE)) -> 2.35 | U21: =IF($H21="","",VLOOKUP($H21,Data!$C$6:$Y$29,13,FALSE)) -> 3.44 | V21: =IF($H21="","",VLOOKUP($H21,Data!$C$6:$Y$29,14,FALSE)) -> 40 | W21: =IF($H21="","",VLOOKUP($H21,Data!$C$6:$Y$29,15,FALSE)) -> 220-240/1/50 | X21: =IF($H21="","",VLOOKUP($H21,Data!$C$6:$Y$29,16,FALSE)) -> 378 | Y21: =IF($H21="","",VLOOKUP($H21,Data!$C$6:$Y$29,17,FALSE)) -> 1115 | Z21: =IF($H21="","",VLOOKUP($H21,Data!$C$6:$Y$29,18,FALSE)) -> 541 | AA21: =IF($H21="","",VLOOKUP($H21,Data!$C$6:$Y$29,19,FALSE)) -> 753 | AB21: =IF($H21="","",VLOOKUP($H21,Data!$C$6:$Y$29,20,FALSE)) -> 855 | AC21: =IF($H21="","",VLOOKUP($H21,Data!$C$6:$Y$29,21,FALSE)) -> 328 | AD21: =IF($H21="","",VLOOKUP($H21,Data!$C$6:$Y$29,22,FALSE)) -> 44 | AE21: =IF($H21="","",VLOOKUP($H21,Data!$C$6:$Y$29,23,FALSE)) -> 51 | AG21: =IF($E21="","",IF($C21="DUCTED",VLOOKUP($E21,'DX-Data'!$D$5:$J$11,7,TRUE),IF($C21="DECORATIVE",VLOOKUP($E21,'DX-Data'!$D$19:$J$23,7,TRUE),IF($C21="PACKAGED",VLOOKUP($E21,'DX-Data'!$D$24:$J$30,7,TRUE),IF($C21="DUCTED-INV",VLOOKUP($E21,'DX-Data'!$D$12:$J$18,7,TRUE),"CHOOSE AC TYPE"))))) -> FDMRN25AVKU - RR25AVKU | AH21: =IF($F$9=TRUE,IF($C21="DUCTED",VLOOKUP($F21,'DX-Data'!$F$5:$J$11,5,TRUE),IF($C21="DECORATIVE",VLOOKUP($F21,'DX-Data'!$F$19:$J$23,5,TRUE),IF($C21="PACKAGED",VLOOKUP($F21,'DX-Data'!$F$24:$J$30,5,TRUE),IF($C21="DUCTED-INV",VLOOKUP($F21,'DX-Data'!$F$12:$J$18,5,TRUE),"CHOOSE AC TYPE")))),"NO SELECTION") -> FDMRN20AVKU - RR20AVKU | AI21: =IF($G$9=TRUE,IF($C21="DUCTED",VLOOKUP($G21,'DX-Data'!$H$5:$J$11,3,TRUE),IF($C21="DECORATIVE",VLOOKUP($G21,'DX-Data'!$H$19:$J$23,3,TRUE),IF($C21="PACKAGED",VLOOKUP($G21,'DX-Data'!$H$24:$J$30,3,TRUE),IF($C21="DUCTED-INV",VLOOKUP($G21,'DX-Data'!$H$12:$J$18,3,TRUE),"CHOOSE AC TYPE")))),"NO SELECTION") -> NO SELECTION | AJ21: =IF($E21="","",IF($C21="DUCTED",VLOOKUP($E21,'DX-Data'!$D$5:$J$11,6,TRUE),IF($C21="DECORATIVE",VLOOKUP($E21,'DX-Data'!$D$19:$J$23,6,TRUE),IF($C21="PACKAGED",VLOOKUP($E21,'DX-Data'!$D$24:$J$30,6,TRUE),IF($C21="DUCTED-INV",VLOOKUP($E21,'DX-Data'!$D$12:$J$18,6,TRUE),0))))) -> 2 | AK21: =IF($F$9=TRUE,IF($C21="DUCTED",VLOOKUP($F21,'DX-Data'!$F$5:$J$11,4,TRUE),IF($C21="DECORATIVE",VLOOKUP($F21,'DX-Data'!$F$19:$J$23,4,TRUE),IF($C21="PACKAGED",VLOOKUP($F21,'DX-Data'!$F$24:$J$30,4,TRUE),IF($C21="DUCTED-INV",VLOOKUP($F21,'DX-Data'!$F$12:$J$18,4,TRUE),"CHOOSE AC TYPE")))),0) -> 1 | AL21: =IF($G$9=TRUE,IF($C21="DUCTED",VLOOKUP($G21,'DX-Data'!$H$5:$J$11,2,TRUE),IF($C21="DECORATIVE",VLOOKUP($G21,'DX-Data'!$H$19:$J$23,2,TRUE),IF($C21="PACKAGED",VLOOKUP($G21,'DX-Data'!$H$24:$J$30,2,TRUE),IF($C21="DUCTED-INV",VLOOKUP($G21,'DX-Data'!$H$12:$J$18,2,TRUE),"CHOOSE AC TYPE")))),0) -> 0 | AM21: =MAX(AJ21:AL21) -> 2 | AN21: =IF(E21="","",VLOOKUP($AM21,'DX-Data'!$I$5:$J$31,2,FALSE)) -> FDMRN25AVKU - RR25AVKU | AO21: =IF(OR(AN21="",AN21=0),"",1) -> 1
B22: GF-DS-03 | C22: DUCTED | D22: TELEPHONE ROOM | E22: 1.4 | F22: 1.2 | G22: 108 | H22: =AN22 -> FDMRN20AVKU - RR20AVKU | I22: =AO22 -> 1 | J22: =IF($H22="","",VLOOKUP($H22,Data!$C$6:$Y$29,2,FALSE)) -> 1.5 | K22: =IF($H22="","",VLOOKUP($H22,Data!$C$6:$Y$29,3,FALSE)) -> Non-Inverter | L22: =IF($H22="","",VLOOKUP($H22,Data!$C$6:$Y$29,4,FALSE)) -> R-410A | M22: =IF($H22="","",VLOOKUP($H22,Data!$C$6:$Y$29,5,FALSE)) -> 24/16 | N22: =IF($H22="","",VLOOKUP($H22,Data!$C$6:$Y$29,6,FALSE)) -> 46 | O22: =IF($H22="","",VLOOKUP($H22,Data!$C$6:$Y$29,7,FALSE)) -> 4.24 | P22: =IF($H22="","",VLOOKUP($H22,Data!$C$6:$Y$29,8,FALSE)) -> 4.11 | Q22: =IF($H22="","",VLOOKUP($H22,Data!$C$6:$Y$29,9,FALSE)) -> 255 | R22: =IF($H22="","",VLOOKUP($H22,Data!$C$6:$Y$29,10,FALSE)) -> MEDIUM | S22: =IF($H22="","",VLOOKUP($H22,Data!$C$6:$Y$29,11,FALSE)) -> 1.77 | T22: =IF($H22="","",VLOOKUP($H22,Data!$C$6:$Y$29,12,FALSE)) -> 1.8 | U22: =IF($H22="","",VLOOKUP($H22,Data!$C$6:$Y$29,13,FALSE)) -> 3.49 | V22: =IF($H22="","",VLOOKUP($H22,Data!$C$6:$Y$29,14,FALSE)) -> 40 | W22: =IF($H22="","",VLOOKUP($H22,Data!$C$6:$Y$29,15,FALSE)) -> 220-240/1/50 | X22: =IF($H22="","",VLOOKUP($H22,Data!$C$6:$Y$29,16,FALSE)) -> 261 | Y22: =IF($H22="","",VLOOKUP($H22,Data!$C$6:$Y$29,17,FALSE)) -> 1200 | Z22: =IF($H22="","",VLOOKUP($H22,Data!$C$6:$Y$29,18,FALSE)) -> 448 | AA22: =IF($H22="","",VLOOKUP($H22,Data!$C$6:$Y$29,19,FALSE)) -> 753 | AB22: =IF($H22="","",VLOOKUP($H22,Data!$C$6:$Y$29,20,FALSE)) -> 855 | AC22: =IF($H22="","",VLOOKUP($H22,Data!$C$6:$Y$29,21,FALSE)) -> 328 | AD22: =IF($H22="","",VLOOKUP($H22,Data!$C$6:$Y$29,22,FALSE)) -> 26 | AE22: =IF($H22="","",VLOOKUP($H22,Data!$C$6:$Y$29,23,FALSE)) -> 47 | AG22: =IF($E22="","",IF($C22="DUCTED",VLOOKUP($E22,'DX-Data'!$D$5:$J$11,7,TRUE),IF($C22="DECORATIVE",VLOOKUP($E22,'DX-Data'!$D$19:$J$23,7,TRUE),IF($C22="PACKAGED",VLOOKUP($E22,'DX-Data'!$D$24:$J$30,7,TRUE),IF($C22="DUCTED-INV",VLOOKUP($E22,'DX-Data'!$D$12:$J$18,7,TRUE),"CHOOSE AC TYPE"))))) -> FDMRN20AVKU - RR20AVKU | AH22: =IF($F$9=TRUE,IF($C22="DUCTED",VLOOKUP($F22,'DX-Data'!$F$5:$J$11,5,TRUE),IF($C22="DECORATIVE",VLOOKUP($F22,'DX-Data'!$F$19:$J$23,5,TRUE),IF($C22="PACKAGED",VLOOKUP($F22,'DX-Data'!$F$24:$J$30,5,TRUE),IF($C22="DUCTED-INV",VLOOKUP($F22,'DX-Data'!$F$12:$J$18,5,TRUE),"CHOOSE AC TYPE")))),"NO SELECTION") -> FDMRN20AVKU - RR20AVKU | AI22: =IF($G$9=TRUE,IF($C22="DUCTED",VLOOKUP($G22,'DX-Data'!$H$5:$J$11,3,TRUE),IF($C22="DECORATIVE",VLOOKUP($G22,'DX-Data'!$H$19:$J$23,3,TRUE),IF($C22="PACKAGED",VLOOKUP($G22,'DX-Data'!$H$24:$J$30,3,TRUE),IF($C22="DUCTED-INV",VLOOKUP($G22,'DX-Data'!$H$12:$J$18,3,TRUE),"CHOOSE AC TYPE")))),"NO SELECTION") -> NO SELECTION | AJ22: =IF($E22="","",IF($C22="DUCTED",VLOOKUP($E22,'DX-Data'!$D$5:$J$11,6,TRUE),IF($C22="DECORATIVE",VLOOKUP($E22,'DX-Data'!$D$19:$J$23,6,TRUE),IF($C22="PACKAGED",VLOOKUP($E22,'DX-Data'!$D$24:$J$30,6,TRUE),IF($C22="DUCTED-INV",VLOOKUP($E22,'DX-Data'!$D$12:$J$18,6,TRUE),0))))) -> 1 | AK22: =IF($F$9=TRUE,IF($C22="DUCTED",VLOOKUP($F22,'DX-Data'!$F$5:$J$11,4,TRUE),IF($C22="DECORATIVE",VLOOKUP($F22,'DX-Data'!$F$19:$J$23,4,TRUE),IF($C22="PACKAGED",VLOOKUP($F22,'DX-Data'!$F$24:$J$30,4,TRUE),IF($C22="DUCTED-INV",VLOOKUP($F22,'DX-Data'!$F$12:$J$18,4,TRUE),"CHOOSE AC TYPE")))),0) -> 1 | AL22: =IF($G$9=TRUE,IF($C22="DUCTED",VLOOKUP($G22,'DX-Data'!$H$5:$J$11,2,TRUE),IF($C22="DECORATIVE",VLOOKUP($G22,'DX-Data'!$H$19:$J$23,2,TRUE),IF($C22="PACKAGED",VLOOKUP($G22,'DX-Data'!$H$24:$J$30,2,TRUE),IF($C22="DUCTED-INV",VLOOKUP($G22,'DX-Data'!$H$12:$J$18,2,TRUE),"CHOOSE AC TYPE")))),0) -> 0 | AM22: =MAX(AJ22:AL22) -> 1 | AN22: =IF(E22="","",VLOOKUP($AM22,'DX-Data'!$I$5:$J$31,2,FALSE)) -> FDMRN20AVKU - RR20AVKU | AO22: =IF(OR(AN22="",AN22=0),"",1) -> 1
B23: GF-DS-04 | C23: DUCTED | D23: GARBAGE ROOM | E23: 4 | F23: 3.7 | G23: 333 | H23: =AN23 -> FDMRN20AVKU - RR20AVKU | I23: =AO23 -> 1 | J23: =IF($H23="","",VLOOKUP($H23,Data!$C$6:$Y$29,2,FALSE)) -> 1.5 | K23: =IF($H23="","",VLOOKUP($H23,Data!$C$6:$Y$29,3,FALSE)) -> Non-Inverter | L23: =IF($H23="","",VLOOKUP($H23,Data!$C$6:$Y$29,4,FALSE)) -> R-410A | M23: =IF($H23="","",VLOOKUP($H23,Data!$C$6:$Y$29,5,FALSE)) -> 24/16 | N23: =IF($H23="","",VLOOKUP($H23,Data!$C$6:$Y$29,6,FALSE)) -> 46 | O23: =IF($H23="","",VLOOKUP($H23,Data!$C$6:$Y$29,7,FALSE)) -> 4.24 | P23: =IF($H23="","",VLOOKUP($H23,Data!$C$6:$Y$29,8,FALSE)) -> 4.11 | Q23: =IF($H23="","",VLOOKUP($H23,Data!$C$6:$Y$29,9,FALSE)) -> 255 | R23: =IF($H23="","",VLOOKUP($H23,Data!$C$6:$Y$29,10,FALSE)) -> MEDIUM | S23: =IF($H23="","",VLOOKUP($H23,Data!$C$6:$Y$29,11,FALSE)) -> 1.77 | T23: =IF($H23="","",VLOOKUP($H23,Data!$C$6:$Y$29,12,FALSE)) -> 1.8 | U23: =IF($H23="","",VLOOKUP($H23,Data!$C$6:$Y$29,13,FALSE)) -> 3.49 | V23: =IF($H23="","",VLOOKUP($H23,Data!$C$6:$Y$29,14,FALSE)) -> 40 | W23: =IF($H23="","",VLOOKUP($H23,Data!$C$6:$Y$29,15,FALSE)) -> 220-240/1/50 | X23: =IF($H23="","",VLOOKUP($H23,Data!$C$6:$Y$29,16,FALSE)) -> 261 | Y23: =IF($H23="","",VLOOKUP($H23,Data!$C$6:$Y$29,17,FALSE)) -> 1200 | Z23: =IF($H23="","",VLOOKUP($H23,Data!$C$6:$Y$29,18,FALSE)) -> 448 | AA23: =IF($H23="","",VLOOKUP($H23,Data!$C$6:$Y$29,19,FALSE)) -> 753 | AB23: =IF($H23="","",VLOOKUP($H23,Data!$C$6:$Y$29,20,FALSE)) -> 855 | AC23: =IF($H23="","",VLOOKUP($H23,Data!$C$6:$Y$29,21,FALSE)) -> 328 | AD23: =IF($H23="","",VLOOKUP($H23,Data!$C$6:$Y$29,22,FALSE)) -> 26 | AE23: =IF($H23="","",VLOOKUP($H23,Data!$C$6:$Y$29,23,FALSE)) -> 47 | AG23: =IF($E23="","",IF($C23="DUCTED",VLOOKUP($E23,'DX-Data'!$D$5:$J$11,7,TRUE),IF($C23="DECORATIVE",VLOOKUP($E23,'DX-Data'!$D$19:$J$23,7,TRUE),IF($C23="PACKAGED",VLOOKUP($E23,'DX-Data'!$D$24:$J$30,7,TRUE),IF($C23="DUCTED-INV",VLOOKUP($E23,'DX-Data'!$D$12:$J$18,7,TRUE),"CHOOSE AC TYPE"))))) -> FDMRN20AVKU - RR20AVKU | AH23: =IF($F$9=TRUE,IF($C23="DUCTED",VLOOKUP($F23,'DX-Data'!$F$5:$J$11,5,TRUE),IF($C23="DECORATIVE",VLOOKUP($F23,'DX-Data'!$F$19:$J$23,5,TRUE),IF($C23="PACKAGED",VLOOKUP($F23,'DX-Data'!$F$24:$J$30,5,TRUE),IF($C23="DUCTED-INV",VLOOKUP($F23,'DX-Data'!$F$12:$J$18,5,TRUE),"CHOOSE AC TYPE")))),"NO SELECTION") -> FDMRN20AVKU - RR20AVKU | AI23: =IF($G$9=TRUE,IF($C23="DUCTED",VLOOKUP($G23,'DX-Data'!$H$5:$J$11,3,TRUE),IF($C23="DECORATIVE",VLOOKUP($G23,'DX-Data'!$H$19:$J$23,3,TRUE),IF($C23="PACKAGED",VLOOKUP($G23,'DX-Data'!$H$24:$J$30,3,TRUE),IF($C23="DUCTED-INV",VLOOKUP($G23,'DX-Data'!$H$12:$J$18,3,TRUE),"CHOOSE AC TYPE")))),"NO SELECTION") -> NO SELECTION | AJ23: =IF($E23="","",IF($C23="DUCTED",VLOOKUP($E23,'DX-Data'!$D$5:$J$11,6,TRUE),IF($C23="DECORATIVE",VLOOKUP($E23,'DX-Data'!$D$19:$J$23,6,TRUE),IF($C23="PACKAGED",VLOOKUP($E23,'DX-Data'!$D$24:$J$30,6,TRUE),IF($C23="DUCTED-INV",VLOOKUP($E23,'DX-Data'!$D$12:$J$18,6,TRUE),0))))) -> 1 | AK23: =IF($F$9=TRUE,IF($C23="DUCTED",VLOOKUP($F23,'DX-Data'!$F$5:$J$11,4,TRUE),IF($C23="DECORATIVE",VLOOKUP($F23,'DX-Data'!$F$19:$J$23,4,TRUE),IF($C23="PACKAGED",VLOOKUP($F23,'DX-Data'!$F$24:$J$30,4,TRUE),IF($C23="DUCTED-INV",VLOOKUP($F23,'DX-Data'!$F$12:$J$18,4,TRUE),"CHOOSE AC TYPE")))),0) -> 1 | AL23: =IF($G$9=TRUE,IF($C23="DUCTED",VLOOKUP($G23,'DX-Data'!$H$5:$J$11,2,TRUE),IF($C23="DECORATIVE",VLOOKUP($G23,'DX-Data'!$H$19:$J$23,2,TRUE),IF($C23="PACKAGED",VLOOKUP($G23,'DX-Data'!$H$24:$J$30,2,TRUE),IF($C23="DUCTED-INV",VLOOKUP($G23,'DX-Data'!$H$12:$J$18,2,TRUE),"CHOOSE AC TYPE")))),0) -> 0 | AM23: =MAX(AJ23:AL23) -> 1 | AN23: =IF(E23="","",VLOOKUP($AM23,'DX-Data'!$I$5:$J$31,2,FALSE)) -> FDMRN20AVKU - RR20AVKU | AO23: =IF(OR(AN23="",AN23=0),"",1) -> 1
B24: GF-DS-05 | C24: DUCTED | D24: CCTV ROOM | E24: 1.6 | F24: 1.5 | G24: 135 | H24: =AN24 -> FDMRN20AVKU - RR20AVKU | I24: =AO24 -> 1 | J24: =IF($H24="","",VLOOKUP($H24,Data!$C$6:$Y$29,2,FALSE)) -> 1.5 | K24: =IF($H24="","",VLOOKUP($H24,Data!$C$6:$Y$29,3,FALSE)) -> Non-Inverter | L24: =IF($H24="","",VLOOKUP($H24,Data!$C$6:$Y$29,4,FALSE)) -> R-410A | M24: =IF($H24="","",VLOOKUP($H24,Data!$C$6:$Y$29,5,FALSE)) -> 24/16 | N24: =IF($H24="","",VLOOKUP($H24,Data!$C$6:$Y$29,6,FALSE)) -> 46 | O24: =IF($H24="","",VLOOKUP($H24,Data!$C$6:$Y$29,7,FALSE)) -> 4.24 | P24: =IF($H24="","",VLOOKUP($H24,Data!$C$6:$Y$29,8,FALSE)) -> 4.11 | Q24: =IF($H24="","",VLOOKUP($H24,Data!$C$6:$Y$29,9,FALSE)) -> 255 | R24: =IF($H24="","",VLOOKUP($H24,Data!$C$6:$Y$29,10,FALSE)) -> MEDIUM | S24: =IF($H24="","",VLOOKUP($H24,Data!$C$6:$Y$29,11,FALSE)) -> 1.77 | T24: =IF($H24="","",VLOOKUP($H24,Data!$C$6:$Y$29,12,FALSE)) -> 1.8 | U24: =IF($H24="","",VLOOKUP($H24,Data!$C$6:$Y$29,13,FALSE)) -> 3.49 | V24: =IF($H24="","",VLOOKUP($H24,Data!$C$6:$Y$29,14,FALSE)) -> 40 | W24: =IF($H24="","",VLOOKUP($H24,Data!$C$6:$Y$29,15,FALSE)) -> 220-240/1/50 | X24: =IF($H24="","",VLOOKUP($H24,Data!$C$6:$Y$29,16,FALSE)) -> 261 | Y24: =IF($H24="","",VLOOKUP($H24,Data!$C$6:$Y$29,17,FALSE)) -> 1200 | Z24: =IF($H24="","",VLOOKUP($H24,Data!$C$6:$Y$29,18,FALSE)) -> 448 | AA24: =IF($H24="","",VLOOKUP($H24,Data!$C$6:$Y$29,19,FALSE)) -> 753 | AB24: =IF($H24="","",VLOOKUP($H24,Data!$C$6:$Y$29,20,FALSE)) -> 855 | AC24: =IF($H24="","",VLOOKUP($H24,Data!$C$6:$Y$29,21,FALSE)) -> 328 | AD24: =IF($H24="","",VLOOKUP($H24,Data!$C$6:$Y$29,22,FALSE)) -> 26 | AE24: =IF($H24="","",VLOOKUP($H24,Data!$C$6:$Y$29,23,FALSE)) -> 47 | AG24: =IF($E24="","",IF($C24="DUCTED",VLOOKUP($E24,'DX-Data'!$D$5:$J$11,7,TRUE),IF($C24="DECORATIVE",VLOOKUP($E24,'DX-Data'!$D$19:$J$23,7,TRUE),IF($C24="PACKAGED",VLOOKUP($E24,'DX-Data'!$D$24:$J$30,7,TRUE),IF($C24="DUCTED-INV",VLOOKUP($E24,'DX-Data'!$D$12:$J$18,7,TRUE),"CHOOSE AC TYPE"))))) -> FDMRN20AVKU - RR20AVKU | AH24: =IF($F$9=TRUE,IF($C24="DUCTED",VLOOKUP($F24,'DX-Data'!$F$5:$J$11,5,TRUE),IF($C24="DECORATIVE",VLOOKUP($F24,'DX-Data'!$F$19:$J$23,5,TRUE),IF($C24="PACKAGED",VLOOKUP($F24,'DX-Data'!$F$24:$J$30,5,TRUE),IF($C24="DUCTED-INV",VLOOKUP($F24,'DX-Data'!$F$12:$J$18,5,TRUE),"CHOOSE AC TYPE")))),"NO SELECTION") -> FDMRN20AVKU - RR20AVKU | AI24: =IF($G$9=TRUE,IF($C24="DUCTED",VLOOKUP($G24,'DX-Data'!$H$5:$J$11,3,TRUE),IF($C24="DECORATIVE",VLOOKUP($G24,'DX-Data'!$H$19:$J$23,3,TRUE),IF($C24="PACKAGED",VLOOKUP($G24,'DX-Data'!$H$24:$J$30,3,TRUE),IF($C24="DUCTED-INV",VLOOKUP($G24,'DX-Data'!$H$12:$J$18,3,TRUE),"CHOOSE AC TYPE")))),"NO SELECTION") -> NO SELECTION | AJ24: =IF($E24="","",IF($C24="DUCTED",VLOOKUP($E24,'DX-Data'!$D$5:$J$11,6,TRUE),IF($C24="DECORATIVE",VLOOKUP($E24,'DX-Data'!$D$19:$J$23,6,TRUE),IF($C24="PACKAGED",VLOOKUP($E24,'DX-Data'!$D$24:$J$30,6,TRUE),IF($C24="DUCTED-INV",VLOOKUP($E24,'DX-Data'!$D$12:$J$18,6,TRUE),0))))) -> 1 | AK24: =IF($F$9=TRUE,IF($C24="DUCTED",VLOOKUP($F24,'DX-Data'!$F$5:$J$11,4,TRUE),IF($C24="DECORATIVE",VLOOKUP($F24,'DX-Data'!$F$19:$J$23,4,TRUE),IF($C24="PACKAGED",VLOOKUP($F24,'DX-Data'!$F$24:$J$30,4,TRUE),IF($C24="DUCTED-INV",VLOOKUP($F24,'DX-Data'!$F$12:$J$18,4,TRUE),"CHOOSE AC TYPE")))),0) -> 1 | AL24: =IF($G$9=TRUE,IF($C24="DUCTED",VLOOKUP($G24,'DX-Data'!$H$5:$J$11,2,TRUE),IF($C24="DECORATIVE",VLOOKUP($G24,'DX-Data'!$H$19:$J$23,2,TRUE),IF($C24="PACKAGED",VLOOKUP($G24,'DX-Data'!$H$24:$J$30,2,TRUE),IF($C24="DUCTED-INV",VLOOKUP($G24,'DX-Data'!$H$12:$J$18,2,TRUE),"CHOOSE AC TYPE")))),0) -> 0 | AM24: =MAX(AJ24:AL24) -> 1 | AN24: =IF(E24="","",VLOOKUP($AM24,'DX-Data'!$I$5:$J$31,2,FALSE)) -> FDMRN20AVKU - RR20AVKU | AO24: =IF(OR(AN24="",AN24=0),"",1) -> 1
B26: PD-DS-01 | C26: DUCTED | D26: LIFT LOBBY | E26: 2.9 | F26: 2.8 | G26: 276 | H26: =AN26 -> FDMRN20AVKU - RR20AVKU | I26: =AO26 -> 1 | J26: =IF($H26="","",VLOOKUP($H26,Data!$C$6:$Y$29,2,FALSE)) -> 1.5 | K26: =IF($H26="","",VLOOKUP($H26,Data!$C$6:$Y$29,3,FALSE)) -> Non-Inverter | L26: =IF($H26="","",VLOOKUP($H26,Data!$C$6:$Y$29,4,FALSE)) -> R-410A | M26: =IF($H26="","",VLOOKUP($H26,Data!$C$6:$Y$29,5,FALSE)) -> 24/16 | N26: =IF($H26="","",VLOOKUP($H26,Data!$C$6:$Y$29,6,FALSE)) -> 46 | O26: =IF($H26="","",VLOOKUP($H26,Data!$C$6:$Y$29,7,FALSE)) -> 4.24 | P26: =IF($H26="","",VLOOKUP($H26,Data!$C$6:$Y$29,8,FALSE)) -> 4.11 | Q26: =IF($H26="","",VLOOKUP($H26,Data!$C$6:$Y$29,9,FALSE)) -> 255 | R26: =IF($H26="","",VLOOKUP($H26,Data!$C$6:$Y$29,10,FALSE)) -> MEDIUM | S26: =IF($H26="","",VLOOKUP($H26,Data!$C$6:$Y$29,11,FALSE)) -> 1.77 | T26: =IF($H26="","",VLOOKUP($H26,Data!$C$6:$Y$29,12,FALSE)) -> 1.8 | U26: =IF($H26="","",VLOOKUP($H26,Data!$C$6:$Y$29,13,FALSE)) -> 3.49 | V26: =IF($H26="","",VLOOKUP($H26,Data!$C$6:$Y$29,14,FALSE)) -> 40 | W26: =IF($H26="","",VLOOKUP($H26,Data!$C$6:$Y$29,15,FALSE)) -> 220-240/1/50 | X26: =IF($H26="","",VLOOKUP($H26,Data!$C$6:$Y$29,16,FALSE)) -> 261 | Y26: =IF($H26="","",VLOOKUP($H26,Data!$C$6:$Y$29,17,FALSE)) -> 1200 | Z26: =IF($H26="","",VLOOKUP($H26,Data!$C$6:$Y$29,18,FALSE)) -> 448 | AA26: =IF($H26="","",VLOOKUP($H26,Data!$C$6:$Y$29,19,FALSE)) -> 753 | AB26: =IF($H26="","",VLOOKUP($H26,Data!$C$6:$Y$29,20,FALSE)) -> 855 | AC26: =IF($H26="","",VLOOKUP($H26,Data!$C$6:$Y$29,21,FALSE)) -> 328 | AD26: =IF($H26="","",VLOOKUP($H26,Data!$C$6:$Y$29,22,FALSE)) -> 26 | AE26: =IF($H26="","",VLOOKUP($H26,Data!$C$6:$Y$29,23,FALSE)) -> 47 | AG26: =IF($E26="","",IF($C26="DUCTED",VLOOKUP($E26,'DX-Data'!$D$5:$J$11,7,TRUE),IF($C26="DECORATIVE",VLOOKUP($E26,'DX-Data'!$D$19:$J$23,7,TRUE),IF($C26="PACKAGED",VLOOKUP($E26,'DX-Data'!$D$24:$J$30,7,TRUE),IF($C26="DUCTED-INV",VLOOKUP($E26,'DX-Data'!$D$12:$J$18,7,TRUE),"CHOOSE AC TYPE"))))) -> FDMRN20AVKU - RR20AVKU | AH26: =IF($F$9=TRUE,IF($C26="DUCTED",VLOOKUP($F26,'DX-Data'!$F$5:$J$11,5,TRUE),IF($C26="DECORATIVE",VLOOKUP($F26,'DX-Data'!$F$19:$J$23,5,TRUE),IF($C26="PACKAGED",VLOOKUP($F26,'DX-Data'!$F$24:$J$30,5,TRUE),IF($C26="DUCTED-INV",VLOOKUP($F26,'DX-Data'!$F$12:$J$18,5,TRUE),"CHOOSE AC TYPE")))),"NO SELECTION") -> FDMRN20AVKU - RR20AVKU | AI26: =IF($G$9=TRUE,IF($C26="DUCTED",VLOOKUP($G26,'DX-Data'!$H$5:$J$11,3,TRUE),IF($C26="DECORATIVE",VLOOKUP($G26,'DX-Data'!$H$19:$J$23,3,TRUE),IF($C26="PACKAGED",VLOOKUP($G26,'DX-Data'!$H$24:$J$30,3,TRUE),IF($C26="DUCTED-INV",VLOOKUP($G26,'DX-Data'!$H$12:$J$18,3,TRUE),"CHOOSE AC TYPE")))),"NO SELECTION") -> NO SELECTION | AJ26: =IF($E26="","",IF($C26="DUCTED",VLOOKUP($E26,'DX-Data'!$D$5:$J$11,6,TRUE),IF($C26="DECORATIVE",VLOOKUP($E26,'DX-Data'!$D$19:$J$23,6,TRUE),IF($C26="PACKAGED",VLOOKUP($E26,'DX-Data'!$D$24:$J$30,6,TRUE),IF($C26="DUCTED-INV",VLOOKUP($E26,'DX-Data'!$D$12:$J$18,6,TRUE),0))))) -> 1 | AK26: =IF($F$9=TRUE,IF($C26="DUCTED",VLOOKUP($F26,'DX-Data'!$F$5:$J$11,4,TRUE),IF($C26="DECORATIVE",VLOOKUP($F26,'DX-Data'!$F$19:$J$23,4,TRUE),IF($C26="PACKAGED",VLOOKUP($F26,'DX-Data'!$F$24:$J$30,4,TRUE),IF($C26="DUCTED-INV",VLOOKUP($F26,'DX-Data'!$F$12:$J$18,4,TRUE),"CHOOSE AC TYPE")))),0) -> 1 | AL26: =IF($G$9=TRUE,IF($C26="DUCTED",VLOOKUP($G26,'DX-Data'!$H$5:$J$11,2,TRUE),IF($C26="DECORATIVE",VLOOKUP($G26,'DX-Data'!$H$19:$J$23,2,TRUE),IF($C26="PACKAGED",VLOOKUP($G26,'DX-Data'!$H$24:$J$30,2,TRUE),IF($C26="DUCTED-INV",VLOOKUP($G26,'DX-Data'!$H$12:$J$18,2,TRUE),"CHOOSE AC TYPE")))),0) -> 0 | AM26: =MAX(AJ26:AL26) -> 1 | AN26: =IF(E26="","",VLOOKUP($AM26,'DX-Data'!$I$5:$J$31,2,FALSE)) -> FDMRN20AVKU - RR20AVKU | AO26: =IF(OR(AN26="",AN26=0),"",1) -> 1
B28: 1F-DS-01 | C28: DUCTED | D28: APT 01 | E28: 9.1 | F28: 7.7 | G28: 757 | H28: =AN28 -> FDMRN50AVKU - RR50AYKU | I28: =AO28 -> 1 | J28: =IF($H28="","",VLOOKUP($H28,Data!$C$6:$Y$29,2,FALSE)) -> 4 | K28: =IF($H28="","",VLOOKUP($H28,Data!$C$6:$Y$29,3,FALSE)) -> Non-Inverter | L28: =IF($H28="","",VLOOKUP($H28,Data!$C$6:$Y$29,4,FALSE)) -> R-410A | M28: =IF($H28="","",VLOOKUP($H28,Data!$C$6:$Y$29,5,FALSE)) -> 24/16 | N28: =IF($H28="","",VLOOKUP($H28,Data!$C$6:$Y$29,6,FALSE)) -> 46 | O28: =IF($H28="","",VLOOKUP($H28,Data!$C$6:$Y$29,7,FALSE)) -> 11.46 | P28: =IF($H28="","",VLOOKUP($H28,Data!$C$6:$Y$29,8,FALSE)) -> 9.96 | Q28: =IF($H28="","",VLOOKUP($H28,Data!$C$6:$Y$29,9,FALSE)) -> 686 | R28: =IF($H28="","",VLOOKUP($H28,Data!$C$6:$Y$29,10,FALSE)) -> MEDIUM | S28: =IF($H28="","",VLOOKUP($H28,Data!$C$6:$Y$29,11,FALSE)) -> 4.7 | T28: =IF($H28="","",VLOOKUP($H28,Data!$C$6:$Y$29,12,FALSE)) -> 4.95 | U28: =IF($H28="","",VLOOKUP($H28,Data!$C$6:$Y$29,13,FALSE)) -> 3.41 | V28: =IF($H28="","",VLOOKUP($H28,Data!$C$6:$Y$29,14,FALSE)) -> 50 | W28: =IF($H28="","",VLOOKUP($H28,Data!$C$6:$Y$29,15,FALSE)) -> 380-415/3/50 | X28: =IF($H28="","",VLOOKUP($H28,Data!$C$6:$Y$29,16,FALSE)) -> 378 | Y28: =IF($H28="","",VLOOKUP($H28,Data!$C$6:$Y$29,17,FALSE)) -> 1569 | Z28: =IF($H28="","",VLOOKUP($H28,Data!$C$6:$Y$29,18,FALSE)) -> 541 | AA28: =IF($H28="","",VLOOKUP($H28,Data!$C$6:$Y$29,19,FALSE)) -> 852 | AB28: =IF($H28="","",VLOOKUP($H28,Data!$C$6:$Y$29,20,FALSE)) -> 1030 | AC28: =IF($H28="","",VLOOKUP($H28,Data!$C$6:$Y$29,21,FALSE)) -> 400 | AD28: =IF($H28="","",VLOOKUP($H28,Data!$C$6:$Y$29,22,FALSE)) -> 56 | AE28: =IF($H28="","",VLOOKUP($H28,Data!$C$6:$Y$29,23,FALSE)) -> 87 | AG28: =IF($E28="","",IF($C28="DUCTED",VLOOKUP($E28,'DX-Data'!$D$5:$J$11,7,TRUE),IF($C28="DECORATIVE",VLOOKUP($E28,'DX-Data'!$D$19:$J$23,7,TRUE),IF($C28="PACKAGED",VLOOKUP($E28,'DX-Data'!$D$24:$J$30,7,TRUE),IF($C28="DUCTED-INV",VLOOKUP($E28,'DX-Data'!$D$12:$J$18,7,TRUE),"CHOOSE AC TYPE"))))) -> FDMRN50AVKU - RR50AYKU | AH28: =IF($F$9=TRUE,IF($C28="DUCTED",VLOOKUP($F28,'DX-Data'!$F$5:$J$11,5,TRUE),IF($C28="DECORATIVE",VLOOKUP($F28,'DX-Data'!$F$19:$J$23,5,TRUE),IF($C28="PACKAGED",VLOOKUP($F28,'DX-Data'!$F$24:$J$30,5,TRUE),IF($C28="DUCTED-INV",VLOOKUP($F28,'DX-Data'!$F$12:$J$18,5,TRUE),"CHOOSE AC TYPE")))),"NO SELECTION") -> FDMRN36AVKU - RR36AVKU | AI28: =IF($G$9=TRUE,IF($C28="DUCTED",VLOOKUP($G28,'DX-Data'!$H$5:$J$11,3,TRUE),IF($C28="DECORATIVE",VLOOKUP($G28,'DX-Data'!$H$19:$J$23,3,TRUE),IF($C28="PACKAGED",VLOOKUP($G28,'DX-Data'!$H$24:$J$30,3,TRUE),IF($C28="DUCTED-INV",VLOOKUP($G28,'DX-Data'!$H$12:$J$18,3,TRUE),"CHOOSE AC TYPE")))),"NO SELECTION") -> NO SELECTION | AJ28: =IF($E28="","",IF($C28="DUCTED",VLOOKUP($E28,'DX-Data'!$D$5:$J$11,6,TRUE),IF($C28="DECORATIVE",VLOOKUP($E28,'DX-Data'!$D$19:$J$23,6,TRUE),IF($C28="PACKAGED",VLOOKUP($E28,'DX-Data'!$D$24:$J$30,6,TRUE),IF($C28="DUCTED-INV",VLOOKUP($E28,'DX-Data'!$D$12:$J$18,6,TRUE),0))))) -> 5 | AK28: =IF($F$9=TRUE,IF($C28="DUCTED",VLOOKUP($F28,'DX-Data'!$F$5:$J$11,4,TRUE),IF($C28="DECORATIVE",VLOOKUP($F28,'DX-Data'!$F$19:$J$23,4,TRUE),IF($C28="PACKAGED",VLOOKUP($F28,'DX-Data'!$F$24:$J$30,4,TRUE),IF($C28="DUCTED-INV",VLOOKUP($F28,'DX-Data'!$F$12:$J$18,4,TRUE),"CHOOSE AC TYPE")))),0) -> 4 | AL28: =IF($G$9=TRUE,IF($C28="DUCTED",VLOOKUP($G28,'DX-Data'!$H$5:$J$11,2,TRUE),IF($C28="DECORATIVE",VLOOKUP($G28,'DX-Data'!$H$19:$J$23,2,TRUE),IF($C28="PACKAGED",VLOOKUP($G28,'DX-Data'!$H$24:$J$30,2,TRUE),IF($C28="DUCTED-INV",VLOOKUP($G28,'DX-Data'!$H$12:$J$18,2,TRUE),"CHOOSE AC TYPE")))),0) -> 0 | AM28: =MAX(AJ28:AL28) -> 5 | AN28: =IF(E28="","",VLOOKUP($AM28,'DX-Data'!$I$5:$J$31,2,FALSE)) -> FDMRN50AVKU - RR50AYKU | AO28: =IF(OR(AN28="",AN28=0),"",1) -> 1
B29: 1F-DS-02 | C29: DUCTED | D29: APT 02 | E29: 4.4 | F29: 3.7 | G29: 309 | H29: =AN29 -> FDMRN25AVKU - RR25AVKU | I29: =AO29 -> 1 | J29: =IF($H29="","",VLOOKUP($H29,Data!$C$6:$Y$29,2,FALSE)) -> 2 | K29: =IF($H29="","",VLOOKUP($H29,Data!$C$6:$Y$29,3,FALSE)) -> Non-Inverter | L29: =IF($H29="","",VLOOKUP($H29,Data!$C$6:$Y$29,4,FALSE)) -> R-410A | M29: =IF($H29="","",VLOOKUP($H29,Data!$C$6:$Y$29,5,FALSE)) -> 24/16 | N29: =IF($H29="","",VLOOKUP($H29,Data!$C$6:$Y$29,6,FALSE)) -> 46 | O29: =IF($H29="","",VLOOKUP($H29,Data!$C$6:$Y$29,7,FALSE)) -> 5.48 | P29: =IF($H29="","",VLOOKUP($H29,Data!$C$6:$Y$29,8,FALSE)) -> 5.05 | Q29: =IF($H29="","",VLOOKUP($H29,Data!$C$6:$Y$29,9,FALSE)) -> 303 | R29: =IF($H29="","",VLOOKUP($H29,Data!$C$6:$Y$29,10,FALSE)) -> MEDIUM | S29: =IF($H29="","",VLOOKUP($H29,Data!$C$6:$Y$29,11,FALSE)) -> 2.29 | T29: =IF($H29="","",VLOOKUP($H29,Data!$C$6:$Y$29,12,FALSE)) -> 2.35 | U29: =IF($H29="","",VLOOKUP($H29,Data!$C$6:$Y$29,13,FALSE)) -> 3.44 | V29: =IF($H29="","",VLOOKUP($H29,Data!$C$6:$Y$29,14,FALSE)) -> 40 | W29: =IF($H29="","",VLOOKUP($H29,Data!$C$6:$Y$29,15,FALSE)) -> 220-240/1/50 | X29: =IF($H29="","",VLOOKUP($H29,Data!$C$6:$Y$29,16,FALSE)) -> 378 | Y29: =IF($H29="","",VLOOKUP($H29,Data!$C$6:$Y$29,17,FALSE)) -> 1115 | Z29: =IF($H29="","",VLOOKUP($H29,Data!$C$6:$Y$29,18,FALSE)) -> 541 | AA29: =IF($H29="","",VLOOKUP($H29,Data!$C$6:$Y$29,19,FALSE)) -> 753 | AB29: =IF($H29="","",VLOOKUP($H29,Data!$C$6:$Y$29,20,FALSE)) -> 855 | AC29: =IF($H29="","",VLOOKUP($H29,Data!$C$6:$Y$29,21,FALSE)) -> 328 | AD29: =IF($H29="","",VLOOKUP($H29,Data!$C$6:$Y$29,22,FALSE)) -> 44 | AE29: =IF($H29="","",VLOOKUP($H29,Data!$C$6:$Y$29,23,FALSE)) -> 51 | AG29: =IF($E29="","",IF($C29="DUCTED",VLOOKUP($E29,'DX-Data'!$D$5:$J$11,7,TRUE),IF($C29="DECORATIVE",VLOOKUP($E29,'DX-Data'!$D$19:$J$23,7,TRUE),IF($C29="PACKAGED",VLOOKUP($E29,'DX-Data'!$D$24:$J$30,7,TRUE),IF($C29="DUCTED-INV",VLOOKUP($E29,'DX-Data'!$D$12:$J$18,7,TRUE),"CHOOSE AC TYPE"))))) -> FDMRN25AVKU - RR25AVKU | AH29: =IF($F$9=TRUE,IF($C29="DUCTED",VLOOKUP($F29,'DX-Data'!$F$5:$J$11,5,TRUE),IF($C29="DECORATIVE",VLOOKUP($F29,'DX-Data'!$F$19:$J$23,5,TRUE),IF($C29="PACKAGED",VLOOKUP($F29,'DX-Data'!$F$24:$J$30,5,TRUE),IF($C29="DUCTED-INV",VLOOKUP($F29,'DX-Data'!$F$12:$J$18,5,TRUE),"CHOOSE AC TYPE")))),"NO SELECTION") -> FDMRN20AVKU - RR20AVKU | AI29: =IF($G$9=TRUE,IF($C29="DUCTED",VLOOKUP($G29,'DX-Data'!$H$5:$J$11,3,TRUE),IF($C29="DECORATIVE",VLOOKUP($G29,'DX-Data'!$H$19:$J$23,3,TRUE),IF($C29="PACKAGED",VLOOKUP($G29,'DX-Data'!$H$24:$J$30,3,TRUE),IF($C29="DUCTED-INV",VLOOKUP($G29,'DX-Data'!$H$12:$J$18,3,TRUE),"CHOOSE AC TYPE")))),"NO SELECTION") -> NO SELECTION | AJ29: =IF($E29="","",IF($C29="DUCTED",VLOOKUP($E29,'DX-Data'!$D$5:$J$11,6,TRUE),IF($C29="DECORATIVE",VLOOKUP($E29,'DX-Data'!$D$19:$J$23,6,TRUE),IF($C29="PACKAGED",VLOOKUP($E29,'DX-Data'!$D$24:$J$30,6,TRUE),IF($C29="DUCTED-INV",VLOOKUP($E29,'DX-Data'!$D$12:$J$18,6,TRUE),0))))) -> 2 | AK29: =IF($F$9=TRUE,IF($C29="DUCTED",VLOOKUP($F29,'DX-Data'!$F$5:$J$11,4,TRUE),IF($C29="DECORATIVE",VLOOKUP($F29,'DX-Data'!$F$19:$J$23,4,TRUE),IF($C29="PACKAGED",VLOOKUP($F29,'DX-Data'!$F$24:$J$30,4,TRUE),IF($C29="DUCTED-INV",VLOOKUP($F29,'DX-Data'!$F$12:$J$18,4,TRUE),"CHOOSE AC TYPE")))),0) -> 1 | AL29: =IF($G$9=TRUE,IF($C29="DUCTED",VLOOKUP($G29,'DX-Data'!$H$5:$J$11,2,TRUE),IF($C29="DECORATIVE",VLOOKUP($G29,'DX-Data'!$H$19:$J$23,2,TRUE),IF($C29="PACKAGED",VLOOKUP($G29,'DX-Data'!$H$24:$J$30,2,TRUE),IF($C29="DUCTED-INV",VLOOKUP($G29,'DX-Data'!$H$12:$J$18,2,TRUE),"CHOOSE AC TYPE")))),0) -> 0 | AM29: =MAX(AJ29:AL29) -> 2 | AN29: =IF(E29="","",VLOOKUP($AM29,'DX-Data'!$I$5:$J$31,2,FALSE)) -> FDMRN25AVKU - RR25AVKU | AO29: =IF(OR(AN29="",AN29=0),"",1) -> 1
B30: 1F-DS-03 | C30: DUCTED | D30: APT 03 | E30: 4.4 | F30: 3.7 | G30: 309 | H30: =AN30 -> FDMRN25AVKU - RR25AVKU | I30: =AO30 -> 1 | J30: =IF($H30="","",VLOOKUP($H30,Data!$C$6:$Y$29,2,FALSE)) -> 2 | K30: =IF($H30="","",VLOOKUP($H30,Data!$C$6:$Y$29,3,FALSE)) -> Non-Inverter | L30: =IF($H30="","",VLOOKUP($H30,Data!$C$6:$Y$29,4,FALSE)) -> R-410A | M30: =IF($H30="","",VLOOKUP($H30,Data!$C$6:$Y$29,5,FALSE)) -> 24/16 | N30: =IF($H30="","",VLOOKUP($H30,Data!$C$6:$Y$29,6,FALSE)) -> 46 | O30: =IF($H30="","",VLOOKUP($H30,Data!$C$6:$Y$29,7,FALSE)) -> 5.48 | P30: =IF($H30="","",VLOOKUP($H30,Data!$C$6:$Y$29,8,FALSE)) -> 5.05 | Q30: =IF($H30="","",VLOOKUP($H30,Data!$C$6:$Y$29,9,FALSE)) -> 303 | R30: =IF($H30="","",VLOOKUP($H30,Data!$C$6:$Y$29,10,FALSE)) -> MEDIUM | S30: =IF($H30="","",VLOOKUP($H30,Data!$C$6:$Y$29,11,FALSE)) -> 2.29 | T30: =IF($H30="","",VLOOKUP($H30,Data!$C$6:$Y$29,12,FALSE)) -> 2.35 | U30: =IF($H30="","",VLOOKUP($H30,Data!$C$6:$Y$29,13,FALSE)) -> 3.44 | V30: =IF($H30="","",VLOOKUP($H30,Data!$C$6:$Y$29,14,FALSE)) -> 40 | W30: =IF($H30="","",VLOOKUP($H30,Data!$C$6:$Y$29,15,FALSE)) -> 220-240/1/50 | X30: =IF($H30="","",VLOOKUP($H30,Data!$C$6:$Y$29,16,FALSE)) -> 378 | Y30: =IF($H30="","",VLOOKUP($H30,Data!$C$6:$Y$29,17,FALSE)) -> 1115 | Z30: =IF($H30="","",VLOOKUP($H30,Data!$C$6:$Y$29,18,FALSE)) -> 541 | AA30: =IF($H30="","",VLOOKUP($H30,Data!$C$6:$Y$29,19,FALSE)) -> 753 | AB30: =IF($H30="","",VLOOKUP($H30,Data!$C$6:$Y$29,20,FALSE)) -> 855 | AC30: =IF($H30="","",VLOOKUP($H30,Data!$C$6:$Y$29,21,FALSE)) -> 328 | AD30: =IF($H30="","",VLOOKUP($H30,Data!$C$6:$Y$29,22,FALSE)) -> 44 | AE30: =IF($H30="","",VLOOKUP($H30,Data!$C$6:$Y$29,23,FALSE)) -> 51 | AG30: =IF($E30="","",IF($C30="DUCTED",VLOOKUP($E30,'DX-Data'!$D$5:$J$11,7,TRUE),IF($C30="DECORATIVE",VLOOKUP($E30,'DX-Data'!$D$19:$J$23,7,TRUE),IF($C30="PACKAGED",VLOOKUP($E30,'DX-Data'!$D$24:$J$30,7,TRUE),IF($C30="DUCTED-INV",VLOOKUP($E30,'DX-Data'!$D$12:$J$18,7,TRUE),"CHOOSE AC TYPE"))))) -> FDMRN25AVKU - RR25AVKU | AH30: =IF($F$9=TRUE,IF($C30="DUCTED",VLOOKUP($F30,'DX-Data'!$F$5:$J$11,5,TRUE),IF($C30="DECORATIVE",VLOOKUP($F30,'DX-Data'!$F$19:$J$23,5,TRUE),IF($C30="PACKAGED",VLOOKUP($F30,'DX-Data'!$F$24:$J$30,5,TRUE),IF($C30="DUCTED-INV",VLOOKUP($F30,'DX-Data'!$F$12:$J$18,5,TRUE),"CHOOSE AC TYPE")))),"NO SELECTION") -> FDMRN20AVKU - RR20AVKU | AI30: =IF($G$9=TRUE,IF($C30="DUCTED",VLOOKUP($G30,'DX-Data'!$H$5:$J$11,3,TRUE),IF($C30="DECORATIVE",VLOOKUP($G30,'DX-Data'!$H$19:$J$23,3,TRUE),IF($C30="PACKAGED",VLOOKUP($G30,'DX-Data'!$H$24:$J$30,3,TRUE),IF($C30="DUCTED-INV",VLOOKUP($G30,'DX-Data'!$H$12:$J$18,3,TRUE),"CHOOSE AC TYPE")))),"NO SELECTION") -> NO SELECTION | AJ30: =IF($E30="","",IF($C30="DUCTED",VLOOKUP($E30,'DX-Data'!$D$5:$J$11,6,TRUE),IF($C30="DECORATIVE",VLOOKUP($E30,'DX-Data'!$D$19:$J$23,6,TRUE),IF($C30="PACKAGED",VLOOKUP($E30,'DX-Data'!$D$24:$J$30,6,TRUE),IF($C30="DUCTED-INV",VLOOKUP($E30,'DX-Data'!$D$12:$J$18,6,TRUE),0))))) -> 2 | AK30: =IF($F$9=TRUE,IF($C30="DUCTED",VLOOKUP($F30,'DX-Data'!$F$5:$J$11,4,TRUE),IF($C30="DECORATIVE",VLOOKUP($F30,'DX-Data'!$F$19:$J$23,4,TRUE),IF($C30="PACKAGED",VLOOKUP($F30,'DX-Data'!$F$24:$J$30,4,TRUE),IF($C30="DUCTED-INV",VLOOKUP($F30,'DX-Data'!$F$12:$J$18,4,TRUE),"CHOOSE AC TYPE")))),0) -> 1 | AL30: =IF($G$9=TRUE,IF($C30="DUCTED",VLOOKUP($G30,'DX-Data'!$H$5:$J$11,2,TRUE),IF($C30="DECORATIVE",VLOOKUP($G30,'DX-Data'!$H$19:$J$23,2,TRUE),IF($C30="PACKAGED",VLOOKUP($G30,'DX-Data'!$H$24:$J$30,2,TRUE),IF($C30="DUCTED-INV",VLOOKUP($G30,'DX-Data'!$H$12:$J$18,2,TRUE),"CHOOSE AC TYPE")))),0) -> 0 | AM30: =MAX(AJ30:AL30) -> 2 | AN30: =IF(E30="","",VLOOKUP($AM30,'DX-Data'!$I$5:$J$31,2,FALSE)) -> FDMRN25AVKU - RR25AVKU | AO30: =IF(OR(AN30="",AN30=0),"",1) -> 1
B31: 1F-DS-04 | C31: DUCTED | D31: APT 04 | E31: 4.4 | F31: 3.7 | G31: 309 | H31: =AN31 -> FDMRN25AVKU - RR25AVKU | I31: =AO31 -> 1 | J31: =IF($H31="","",VLOOKUP($H31,Data!$C$6:$Y$29,2,FALSE)) -> 2 | K31: =IF($H31="","",VLOOKUP($H31,Data!$C$6:$Y$29,3,FALSE)) -> Non-Inverter | L31: =IF($H31="","",VLOOKUP($H31,Data!$C$6:$Y$29,4,FALSE)) -> R-410A | M31: =IF($H31="","",VLOOKUP($H31,Data!$C$6:$Y$29,5,FALSE)) -> 24/16 | N31: =IF($H31="","",VLOOKUP($H31,Data!$C$6:$Y$29,6,FALSE)) -> 46 | O31: =IF($H31="","",VLOOKUP($H31,Data!$C$6:$Y$29,7,FALSE)) -> 5.48 | P31: =IF($H31="","",VLOOKUP($H31,Data!$C$6:$Y$29,8,FALSE)) -> 5.05 | Q31: =IF($H31="","",VLOOKUP($H31,Data!$C$6:$Y$29,9,FALSE)) -> 303 | R31: =IF($H31="","",VLOOKUP($H31,Data!$C$6:$Y$29,10,FALSE)) -> MEDIUM | S31: =IF($H31="","",VLOOKUP($H31,Data!$C$6:$Y$29,11,FALSE)) -> 2.29 | T31: =IF($H31="","",VLOOKUP($H31,Data!$C$6:$Y$29,12,FALSE)) -> 2.35 | U31: =IF($H31="","",VLOOKUP($H31,Data!$C$6:$Y$29,13,FALSE)) -> 3.44 | V31: =IF($H31="","",VLOOKUP($H31,Data!$C$6:$Y$29,14,FALSE)) -> 40 | W31: =IF($H31="","",VLOOKUP($H31,Data!$C$6:$Y$29,15,FALSE)) -> 220-240/1/50 | X31: =IF($H31="","",VLOOKUP($H31,Data!$C$6:$Y$29,16,FALSE)) -> 378 | Y31: =IF($H31="","",VLOOKUP($H31,Data!$C$6:$Y$29,17,FALSE)) -> 1115 | Z31: =IF($H31="","",VLOOKUP($H31,Data!$C$6:$Y$29,18,FALSE)) -> 541 | AA31: =IF($H31="","",VLOOKUP($H31,Data!$C$6:$Y$29,19,FALSE)) -> 753 | AB31: =IF($H31="","",VLOOKUP($H31,Data!$C$6:$Y$29,20,FALSE)) -> 855 | AC31: =IF($H31="","",VLOOKUP($H31,Data!$C$6:$Y$29,21,FALSE)) -> 328 | AD31: =IF($H31="","",VLOOKUP($H31,Data!$C$6:$Y$29,22,FALSE)) -> 44 | AE31: =IF($H31="","",VLOOKUP($H31,Data!$C$6:$Y$29,23,FALSE)) -> 51 | AG31: =IF($E31="","",IF($C31="DUCTED",VLOOKUP($E31,'DX-Data'!$D$5:$J$11,7,TRUE),IF($C31="DECORATIVE",VLOOKUP($E31,'DX-Data'!$D$19:$J$23,7,TRUE),IF($C31="PACKAGED",VLOOKUP($E31,'DX-Data'!$D$24:$J$30,7,TRUE),IF($C31="DUCTED-INV",VLOOKUP($E31,'DX-Data'!$D$12:$J$18,7,TRUE),"CHOOSE AC TYPE"))))) -> FDMRN25AVKU - RR25AVKU | AH31: =IF($F$9=TRUE,IF($C31="DUCTED",VLOOKUP($F31,'DX-Data'!$F$5:$J$11,5,TRUE),IF($C31="DECORATIVE",VLOOKUP($F31,'DX-Data'!$F$19:$J$23,5,TRUE),IF($C31="PACKAGED",VLOOKUP($F31,'DX-Data'!$F$24:$J$30,5,TRUE),IF($C31="DUCTED-INV",VLOOKUP($F31,'DX-Data'!$F$12:$J$18,5,TRUE),"CHOOSE AC TYPE")))),"NO SELECTION") -> FDMRN20AVKU - RR20AVKU | AI31: =IF($G$9=TRUE,IF($C31="DUCTED",VLOOKUP($G31,'DX-Data'!$H$5:$J$11,3,TRUE),IF($C31="DECORATIVE",VLOOKUP($G31,'DX-Data'!$H$19:$J$23,3,TRUE),IF($C31="PACKAGED",VLOOKUP($G31,'DX-Data'!$H$24:$J$30,3,TRUE),IF($C31="DUCTED-INV",VLOOKUP($G31,'DX-Data'!$H$12:$J$18,3,TRUE),"CHOOSE AC TYPE")))),"NO SELECTION") -> NO SELECTION | AJ31: =IF($E31="","",IF($C31="DUCTED",VLOOKUP($E31,'DX-Data'!$D$5:$J$11,6,TRUE),IF($C31="DECORATIVE",VLOOKUP($E31,'DX-Data'!$D$19:$J$23,6,TRUE),IF($C31="PACKAGED",VLOOKUP($E31,'DX-Data'!$D$24:$J$30,6,TRUE),IF($C31="DUCTED-INV",VLOOKUP($E31,'DX-Data'!$D$12:$J$18,6,TRUE),0))))) -> 2 | AK31: =IF($F$9=TRUE,IF($C31="DUCTED",VLOOKUP($F31,'DX-Data'!$F$5:$J$11,4,TRUE),IF($C31="DECORATIVE",VLOOKUP($F31,'DX-Data'!$F$19:$J$23,4,TRUE),IF($C31="PACKAGED",VLOOKUP($F31,'DX-Data'!$F$24:$J$30,4,TRUE),IF($C31="DUCTED-INV",VLOOKUP($F31,'DX-Data'!$F$12:$J$18,4,TRUE),"CHOOSE AC TYPE")))),0) -> 1 | AL31: =IF($G$9=TRUE,IF($C31="DUCTED",VLOOKUP($G31,'DX-Data'!$H$5:$J$11,2,TRUE),IF($C31="DECORATIVE",VLOOKUP($G31,'DX-Data'!$H$19:$J$23,2,TRUE),IF($C31="PACKAGED",VLOOKUP($G31,'DX-Data'!$H$24:$J$30,2,TRUE),IF($C31="DUCTED-INV",VLOOKUP($G31,'DX-Data'!$H$12:$J$18,2,TRUE),"CHOOSE AC TYPE")))),0) -> 0 | AM31: =MAX(AJ31:AL31) -> 2 | AN31: =IF(E31="","",VLOOKUP($AM31,'DX-Data'!$I$5:$J$31,2,FALSE)) -> FDMRN25AVKU - RR25AVKU | AO31: =IF(OR(AN31="",AN31=0),"",1) -> 1
B32: 1F-DS-05 | C32: DUCTED | D32: APT 05 | E32: 10.3 | F32: 8.8 | G32: 727 | H32: =AN32 -> FDMRN50AVKU - RR50AYKU | I32: =AO32 -> 1 | J32: =IF($H32="","",VLOOKUP($H32,Data!$C$6:$Y$29,2,FALSE)) -> 4 | K32: =IF($H32="","",VLOOKUP($H32,Data!$C$6:$Y$29,3,FALSE)) -> Non-Inverter | L32: =IF($H32="","",VLOOKUP($H32,Data!$C$6:$Y$29,4,FALSE)) -> R-410A | M32: =IF($H32="","",VLOOKUP($H32,Data!$C$6:$Y$29,5,FALSE)) -> 24/16 | N32: =IF($H32="","",VLOOKUP($H32,Data!$C$6:$Y$29,6,FALSE)) -> 46 | O32: =IF($H32="","",VLOOKUP($H32,Data!$C$6:$Y$29,7,FALSE)) -> 11.46 | P32: =IF($H32="","",VLOOKUP($H32,Data!$C$6:$Y$29,8,FALSE)) -> 9.96 | Q32: =IF($H32="","",VLOOKUP($H32,Data!$C$6:$Y$29,9,FALSE)) -> 686 | R32: =IF($H32="","",VLOOKUP($H32,Data!$C$6:$Y$29,10,FALSE)) -> MEDIUM | S32: =IF($H32="","",VLOOKUP($H32,Data!$C$6:$Y$29,11,FALSE)) -> 4.7 | T32: =IF($H32="","",VLOOKUP($H32,Data!$C$6:$Y$29,12,FALSE)) -> 4.95 | U32: =IF($H32="","",VLOOKUP($H32,Data!$C$6:$Y$29,13,FALSE)) -> 3.41 | V32: =IF($H32="","",VLOOKUP($H32,Data!$C$6:$Y$29,14,FALSE)) -> 50 | W32: =IF($H32="","",VLOOKUP($H32,Data!$C$6:$Y$29,15,FALSE)) -> 380-415/3/50 | X32: =IF($H32="","",VLOOKUP($H32,Data!$C$6:$Y$29,16,FALSE)) -> 378 | Y32: =IF($H32="","",VLOOKUP($H32,Data!$C$6:$Y$29,17,FALSE)) -> 1569 | Z32: =IF($H32="","",VLOOKUP($H32,Data!$C$6:$Y$29,18,FALSE)) -> 541 | AA32: =IF($H32="","",VLOOKUP($H32,Data!$C$6:$Y$29,19,FALSE)) -> 852 | AB32: =IF($H32="","",VLOOKUP($H32,Data!$C$6:$Y$29,20,FALSE)) -> 1030 | AC32: =IF($H32="","",VLOOKUP($H32,Data!$C$6:$Y$29,21,FALSE)) -> 400 | AD32: =IF($H32="","",VLOOKUP($H32,Data!$C$6:$Y$29,22,FALSE)) -> 56 | AE32: =IF($H32="","",VLOOKUP($H32,Data!$C$6:$Y$29,23,FALSE)) -> 87 | AG32: =IF($E32="","",IF($C32="DUCTED",VLOOKUP($E32,'DX-Data'!$D$5:$J$11,7,TRUE),IF($C32="DECORATIVE",VLOOKUP($E32,'DX-Data'!$D$19:$J$23,7,TRUE),IF($C32="PACKAGED",VLOOKUP($E32,'DX-Data'!$D$24:$J$30,7,TRUE),IF($C32="DUCTED-INV",VLOOKUP($E32,'DX-Data'!$D$12:$J$18,7,TRUE),"CHOOSE AC TYPE"))))) -> FDMRN50AVKU - RR50AYKU | AH32: =IF($F$9=TRUE,IF($C32="DUCTED",VLOOKUP($F32,'DX-Data'!$F$5:$J$11,5,TRUE),IF($C32="DECORATIVE",VLOOKUP($F32,'DX-Data'!$F$19:$J$23,5,TRUE),IF($C32="PACKAGED",VLOOKUP($F32,'DX-Data'!$F$24:$J$30,5,TRUE),IF($C32="DUCTED-INV",VLOOKUP($F32,'DX-Data'!$F$12:$J$18,5,TRUE),"CHOOSE AC TYPE")))),"NO SELECTION") -> FDMRN50AVKU - RR50AYKU | AI32: =IF($G$9=TRUE,IF($C32="DUCTED",VLOOKUP($G32,'DX-Data'!$H$5:$J$11,3,TRUE),IF($C32="DECORATIVE",VLOOKUP($G32,'DX-Data'!$H$19:$J$23,3,TRUE),IF($C32="PACKAGED",VLOOKUP($G32,'DX-Data'!$H$24:$J$30,3,TRUE),IF($C32="DUCTED-INV",VLOOKUP($G32,'DX-Data'!$H$12:$J$18,3,TRUE),"CHOOSE AC TYPE")))),"NO SELECTION") -> NO SELECTION | AJ32: =IF($E32="","",IF($C32="DUCTED",VLOOKUP($E32,'DX-Data'!$D$5:$J$11,6,TRUE),IF($C32="DECORATIVE",VLOOKUP($E32,'DX-Data'!$D$19:$J$23,6,TRUE),IF($C32="PACKAGED",VLOOKUP($E32,'DX-Data'!$D$24:$J$30,6,TRUE),IF($C32="DUCTED-INV",VLOOKUP($E32,'DX-Data'!$D$12:$J$18,6,TRUE),0))))) -> 5 | AK32: =IF($F$9=TRUE,IF($C32="DUCTED",VLOOKUP($F32,'DX-Data'!$F$5:$J$11,4,TRUE),IF($C32="DECORATIVE",VLOOKUP($F32,'DX-Data'!$F$19:$J$23,4,TRUE),IF($C32="PACKAGED",VLOOKUP($F32,'DX-Data'!$F$24:$J$30,4,TRUE),IF($C32="DUCTED-INV",VLOOKUP($F32,'DX-Data'!$F$12:$J$18,4,TRUE),"CHOOSE AC TYPE")))),0) -> 5 | AL32: =IF($G$9=TRUE,IF($C32="DUCTED",VLOOKUP($G32,'DX-Data'!$H$5:$J$11,2,TRUE),IF($C32="DECORATIVE",VLOOKUP($G32,'DX-Data'!$H$19:$J$23,2,TRUE),IF($C32="PACKAGED",VLOOKUP($G32,'DX-Data'!$H$24:$J$30,2,TRUE),IF($C32="DUCTED-INV",VLOOKUP($G32,'DX-Data'!$H$12:$J$18,2,TRUE),"CHOOSE AC TYPE")))),0) -> 0 | AM32: =MAX(AJ32:AL32) -> 5 | AN32: =IF(E32="","",VLOOKUP($AM32,'DX-Data'!$I$5:$J$31,2,FALSE)) -> FDMRN50AVKU - RR50AYKU | AO32: =IF(OR(AN32="",AN32=0),"",1) -> 1
B33: 1F-DS-06 | C33: DUCTED | D33: APT 06 | E33: 9.6 | F33: 8.1 | G33: 672 | H33: =AN33 -> FDMRN50AVKU - RR50AYKU | I33: =AO33 -> 1 | J33: =IF($H33="","",VLOOKUP($H33,Data!$C$6:$Y$29,2,FALSE)) -> 4 | K33: =IF($H33="","",VLOOKUP($H33,Data!$C$6:$Y$29,3,FALSE)) -> Non-Inverter | L33: =IF($H33="","",VLOOKUP($H33,Data!$C$6:$Y$29,4,FALSE)) -> R-410A | M33: =IF($H33="","",VLOOKUP($H33,Data!$C$6:$Y$29,5,FALSE)) -> 24/16 | N33: =IF($H33="","",VLOOKUP($H33,Data!$C$6:$Y$29,6,FALSE)) -> 46 | O33: =IF($H33="","",VLOOKUP($H33,Data!$C$6:$Y$29,7,FALSE)) -> 11.46 | P33: =IF($H33="","",VLOOKUP($H33,Data!$C$6:$Y$29,8,FALSE)) -> 9.96 | Q33: =IF($H33="","",VLOOKUP($H33,Data!$C$6:$Y$29,9,FALSE)) -> 686 | R33: =IF($H33="","",VLOOKUP($H33,Data!$C$6:$Y$29,10,FALSE)) -> MEDIUM | S33: =IF($H33="","",VLOOKUP($H33,Data!$C$6:$Y$29,11,FALSE)) -> 4.7 | T33: =IF($H33="","",VLOOKUP($H33,Data!$C$6:$Y$29,12,FALSE)) -> 4.95 | U33: =IF($H33="","",VLOOKUP($H33,Data!$C$6:$Y$29,13,FALSE)) -> 3.41 | V33: =IF($H33="","",VLOOKUP($H33,Data!$C$6:$Y$29,14,FALSE)) -> 50 | W33: =IF($H33="","",VLOOKUP($H33,Data!$C$6:$Y$29,15,FALSE)) -> 380-415/3/50 | X33: =IF($H33="","",VLOOKUP($H33,Data!$C$6:$Y$29,16,FALSE)) -> 378 | Y33: =IF($H33="","",VLOOKUP($H33,Data!$C$6:$Y$29,17,FALSE)) -> 1569 | Z33: =IF($H33="","",VLOOKUP($H33,Data!$C$6:$Y$29,18,FALSE)) -> 541 | AA33: =IF($H33="","",VLOOKUP($H33,Data!$C$6:$Y$29,19,FALSE)) -> 852 | AB33: =IF($H33="","",VLOOKUP($H33,Data!$C$6:$Y$29,20,FALSE)) -> 1030 | AC33: =IF($H33="","",VLOOKUP($H33,Data!$C$6:$Y$29,21,FALSE)) -> 400 | AD33: =IF($H33="","",VLOOKUP($H33,Data!$C$6:$Y$29,22,FALSE)) -> 56 | AE33: =IF($H33="","",VLOOKUP($H33,Data!$C$6:$Y$29,23,FALSE)) -> 87 | AG33: =IF($E33="","",IF($C33="DUCTED",VLOOKUP($E33,'DX-Data'!$D$5:$J$11,7,TRUE),IF($C33="DECORATIVE",VLOOKUP($E33,'DX-Data'!$D$19:$J$23,7,TRUE),IF($C33="PACKAGED",VLOOKUP($E33,'DX-Data'!$D$24:$J$30,7,TRUE),IF($C33="DUCTED-INV",VLOOKUP($E33,'DX-Data'!$D$12:$J$18,7,TRUE),"CHOOSE AC TYPE"))))) -> FDMRN50AVKU - RR50AYKU | AH33: =IF($F$9=TRUE,IF($C33="DUCTED",VLOOKUP($F33,'DX-Data'!$F$5:$J$11,5,TRUE),IF($C33="DECORATIVE",VLOOKUP($F33,'DX-Data'!$F$19:$J$23,5,TRUE),IF($C33="PACKAGED",VLOOKUP($F33,'DX-Data'!$F$24:$J$30,5,TRUE),IF($C33="DUCTED-INV",VLOOKUP($F33,'DX-Data'!$F$12:$J$18,5,TRUE),"CHOOSE AC TYPE")))),"NO SELECTION") -> FDMRN36AVKU - RR36AVKU | AI33: =IF($G$9=TRUE,IF($C33="DUCTED",VLOOKUP($G33,'DX-Data'!$H$5:$J$11,3,TRUE),IF($C33="DECORATIVE",VLOOKUP($G33,'DX-Data'!$H$19:$J$23,3,TRUE),IF($C33="PACKAGED",VLOOKUP($G33,'DX-Data'!$H$24:$J$30,3,TRUE),IF($C33="DUCTED-INV",VLOOKUP($G33,'DX-Data'!$H$12:$J$18,3,TRUE),"CHOOSE AC TYPE")))),"NO SELECTION") -> NO SELECTION | AJ33: =IF($E33="","",IF($C33="DUCTED",VLOOKUP($E33,'DX-Data'!$D$5:$J$11,6,TRUE),IF($C33="DECORATIVE",VLOOKUP($E33,'DX-Data'!$D$19:$J$23,6,TRUE),IF($C33="PACKAGED",VLOOKUP($E33,'DX-Data'!$D$24:$J$30,6,TRUE),IF($C33="DUCTED-INV",VLOOKUP($E33,'DX-Data'!$D$12:$J$18,6,TRUE),0))))) -> 5 | AK33: =IF($F$9=TRUE,IF($C33="DUCTED",VLOOKUP($F33,'DX-Data'!$F$5:$J$11,4,TRUE),IF($C33="DECORATIVE",VLOOKUP($F33,'DX-Data'!$F$19:$J$23,4,TRUE),IF($C33="PACKAGED",VLOOKUP($F33,'DX-Data'!$F$24:$J$30,4,TRUE),IF($C33="DUCTED-INV",VLOOKUP($F33,'DX-Data'!$F$12:$J$18,4,TRUE),"CHOOSE AC TYPE")))),0) -> 4 | AL33: =IF($G$9=TRUE,IF($C33="DUCTED",VLOOKUP($G33,'DX-Data'!$H$5:$J$11,2,TRUE),IF($C33="DECORATIVE",VLOOKUP($G33,'DX-Data'!$H$19:$J$23,2,TRUE),IF($C33="PACKAGED",VLOOKUP($G33,'DX-Data'!$H$24:$J$30,2,TRUE),IF($C33="DUCTED-INV",VLOOKUP($G33,'DX-Data'!$H$12:$J$18,2,TRUE),"CHOOSE AC TYPE")))),0) -> 0 | AM33: =MAX(AJ33:AL33) -> 5 | AN33: =IF(E33="","",VLOOKUP($AM33,'DX-Data'!$I$5:$J$31,2,FALSE)) -> FDMRN50AVKU - RR50AYKU | AO33: =IF(OR(AN33="",AN33=0),"",1) -> 1
B34: 1F-DS-07 | C34: DUCTED | D34: APT 07 | E34: 4.5 | F34: 3.8 | G34: 313 | H34: =AN34 -> FDMRN25AVKU - RR25AVKU | I34: =AO34 -> 1 | J34: =IF($H34="","",VLOOKUP($H34,Data!$C$6:$Y$29,2,FALSE)) -> 2 | K34: =IF($H34="","",VLOOKUP($H34,Data!$C$6:$Y$29,3,FALSE)) -> Non-Inverter | L34: =IF($H34="","",VLOOKUP($H34,Data!$C$6:$Y$29,4,FALSE)) -> R-410A | M34: =IF($H34="","",VLOOKUP($H34,Data!$C$6:$Y$29,5,FALSE)) -> 24/16 | N34: =IF($H34="","",VLOOKUP($H34,Data!$C$6:$Y$29,6,FALSE)) -> 46 | O34: =IF($H34="","",VLOOKUP($H34,Data!$C$6:$Y$29,7,FALSE)) -> 5.48 | P34: =IF($H34="","",VLOOKUP($H34,Data!$C$6:$Y$29,8,FALSE)) -> 5.05 | Q34: =IF($H34="","",VLOOKUP($H34,Data!$C$6:$Y$29,9,FALSE)) -> 303 | R34: =IF($H34="","",VLOOKUP($H34,Data!$C$6:$Y$29,10,FALSE)) -> MEDIUM | S34: =IF($H34="","",VLOOKUP($H34,Data!$C$6:$Y$29,11,FALSE)) -> 2.29 | T34: =IF($H34="","",VLOOKUP($H34,Data!$C$6:$Y$29,12,FALSE)) -> 2.35 | U34: =IF($H34="","",VLOOKUP($H34,Data!$C$6:$Y$29,13,FALSE)) -> 3.44 | V34: =IF($H34="","",VLOOKUP($H34,Data!$C$6:$Y$29,14,FALSE)) -> 40 | W34: =IF($H34="","",VLOOKUP($H34,Data!$C$6:$Y$29,15,FALSE)) -> 220-240/1/50 | X34: =IF($H34="","",VLOOKUP($H34,Data!$C$6:$Y$29,16,FALSE)) -> 378 | Y34: =IF($H34="","",VLOOKUP($H34,Data!$C$6:$Y$29,17,FALSE)) -> 1115 | Z34: =IF($H34="","",VLOOKUP($H34,Data!$C$6:$Y$29,18,FALSE)) -> 541 | AA34: =IF($H34="","",VLOOKUP($H34,Data!$C$6:$Y$29,19,FALSE)) -> 753 | AB34: =IF($H34="","",VLOOKUP($H34,Data!$C$6:$Y$29,20,FALSE)) -> 855 | AC34: =IF($H34="","",VLOOKUP($H34,Data!$C$6:$Y$29,21,FALSE)) -> 328 | AD34: =IF($H34="","",VLOOKUP($H34,Data!$C$6:$Y$29,22,FALSE)) -> 44 | AE34: =IF($H34="","",VLOOKUP($H34,Data!$C$6:$Y$29,23,FALSE)) -> 51 | AG34: =IF($E34="","",IF($C34="DUCTED",VLOOKUP($E34,'DX-Data'!$D$5:$J$11,7,TRUE),IF($C34="DECORATIVE",VLOOKUP($E34,'DX-Data'!$D$19:$J$23,7,TRUE),IF($C34="PACKAGED",VLOOKUP($E34,'DX-Data'!$D$24:$J$30,7,TRUE),IF($C34="DUCTED-INV",VLOOKUP($E34,'DX-Data'!$D$12:$J$18,7,TRUE),"CHOOSE AC TYPE"))))) -> FDMRN25AVKU - RR25AVKU | AH34: =IF($F$9=TRUE,IF($C34="DUCTED",VLOOKUP($F34,'DX-Data'!$F$5:$J$11,5,TRUE),IF($C34="DECORATIVE",VLOOKUP($F34,'DX-Data'!$F$19:$J$23,5,TRUE),IF($C34="PACKAGED",VLOOKUP($F34,'DX-Data'!$F$24:$J$30,5,TRUE),IF($C34="DUCTED-INV",VLOOKUP($F34,'DX-Data'!$F$12:$J$18,5,TRUE),"CHOOSE AC TYPE")))),"NO SELECTION") -> FDMRN20AVKU - RR20AVKU | AI34: =IF($G$9=TRUE,IF($C34="DUCTED",VLOOKUP($G34,'DX-Data'!$H$5:$J$11,3,TRUE),IF($C34="DECORATIVE",VLOOKUP($G34,'DX-Data'!$H$19:$J$23,3,TRUE),IF($C34="PACKAGED",VLOOKUP($G34,'DX-Data'!$H$24:$J$30,3,TRUE),IF($C34="DUCTED-INV",VLOOKUP($G34,'DX-Data'!$H$12:$J$18,3,TRUE),"CHOOSE AC TYPE")))),"NO SELECTION") -> NO SELECTION | AJ34: =IF($E34="","",IF($C34="DUCTED",VLOOKUP($E34,'DX-Data'!$D$5:$J$11,6,TRUE),IF($C34="DECORATIVE",VLOOKUP($E34,'DX-Data'!$D$19:$J$23,6,TRUE),IF($C34="PACKAGED",VLOOKUP($E34,'DX-Data'!$D$24:$J$30,6,TRUE),IF($C34="DUCTED-INV",VLOOKUP($E34,'DX-Data'!$D$12:$J$18,6,TRUE),0))))) -> 2 | AK34: =IF($F$9=TRUE,IF($C34="DUCTED",VLOOKUP($F34,'DX-Data'!$F$5:$J$11,4,TRUE),IF($C34="DECORATIVE",VLOOKUP($F34,'DX-Data'!$F$19:$J$23,4,TRUE),IF($C34="PACKAGED",VLOOKUP($F34,'DX-Data'!$F$24:$J$30,4,TRUE),IF($C34="DUCTED-INV",VLOOKUP($F34,'DX-Data'!$F$12:$J$18,4,TRUE),"CHOOSE AC TYPE")))),0) -> 1 | AL34: =IF($G$9=TRUE,IF($C34="DUCTED",VLOOKUP($G34,'DX-Data'!$H$5:$J$11,2,TRUE),IF($C34="DECORATIVE",VLOOKUP($G34,'DX-Data'!$H$19:$J$23,2,TRUE),IF($C34="PACKAGED",VLOOKUP($G34,'DX-Data'!$H$24:$J$30,2,TRUE),IF($C34="DUCTED-INV",VLOOKUP($G34,'DX-Data'!$H$12:$J$18,2,TRUE),"CHOOSE AC TYPE")))),0) -> 0 | AM34: =MAX(AJ34:AL34) -> 2 | AN34: =IF(E34="","",VLOOKUP($AM34,'DX-Data'!$I$5:$J$31,2,FALSE)) -> FDMRN25AVKU - RR25AVKU | AO34: =IF(OR(AN34="",AN34=0),"",1) -> 1
... B44: 1F-DS-16B | C44: DUCTED | D44: APT 16 BEDROOM | E44: 3.9 | F44: 3.6 | G44: 303 | H44: =AN44 -> FDMRN20AVKU - RR20AVKU | I44: =AO44 -> 1 | J44: =IF($H44="","",VLOOKUP($H44,Data!$C$6:$Y$29,2,FALSE)) -> 1.5 | K44: =IF($H44="","",VLOOKUP($H44,Data!$C$6:$Y$29,3,FALSE)) -> Non-Inverter | L44: =IF($H44="","",VLOOKUP($H44,Data!$C$6:$Y$29,4,FALSE)) -> R-410A | M44: =IF($H44="","",VLOOKUP($H44,Data!$C$6:$Y$29,5,FALSE)) -> 24/16 | N44: =IF($H44="","",VLOOKUP($H44,Data!$C$6:$Y$29,6,FALSE)) -> 46 | O44: =IF($H44="","",VLOOKUP($H44,Data!$C$6:$Y$29,7,FALSE)) -> 4.24 | P44: =IF($H44="","",VLOOKUP($H44,Data!$C$6:$Y$29,8,FALSE)) -> 4.11 | Q44: =IF($H44="","",VLOOKUP($H44,Data!$C$6:$Y$29,9,FALSE)) -> 255 | R44: =IF($H44="","",VLOOKUP($H44,Data!$C$6:$Y$29,10,FALSE)) -> MEDIUM | S44: =IF($H44="","",VLOOKUP($H44,Data!$C$6:$Y$29,11,FALSE)) -> 1.77 | T44: =IF($H44="","",VLOOKUP($H44,Data!$C$6:$Y$29,12,FALSE)) -> 1.8 | U44: =IF($H44="","",VLOOKUP($H44,Data!$C$6:$Y$29,13,FALSE)) -> 3.49 | V44: =IF($H44="","",VLOOKUP($H44,Data!$C$6:$Y$29,14,FALSE)) -> 40 | W44: =IF($H44="","",VLOOKUP($H44,Data!$C$6:$Y$29,15,FALSE)) -> 220-240/1/50 | X44: =IF($H44="","",VLOOKUP($H44,Data!$C$6:$Y$29,16,FALSE)) -> 261 | Y44: =IF($H44="","",VLOOKUP($H44,Data!$C$6:$Y$29,17,FALSE)) -> 1200 | Z44: =IF($H44="","",VLOOKUP($H44,Data!$C$6:$Y$29,18,FALSE)) -> 448 | AA44: =IF($H44="","",VLOOKUP($H44,Data!$C$6:$Y$29,19,FALSE)) -> 753 | AB44: =IF($H44="","",VLOOKUP($H44,Data!$C$6:$Y$29,20,FALSE)) -> 855 | AC44: =IF($H44="","",VLOOKUP($H44,Data!$C$6:$Y$29,21,FALSE)) -> 328 | AD44: =IF($H44="","",VLOOKUP($H44,Data!$C$6:$Y$29,22,FALSE)) -> 26 | AE44: =IF($H44="","",VLOOKUP($H44,Data!$C$6:$Y$29,23,FALSE)) -> 47 | AG44: =IF($E44="","",IF($C44="DUCTED",VLOOKUP($E44,'DX-Data'!$D$5:$J$11,7,TRUE),IF($C44="DECORATIVE",VLOOKUP($E44,'DX-Data'!$D$19:$J$23,7,TRUE),IF($C44="PACKAGED",VLOOKUP($E44,'DX-Data'!$D$24:$J$30,7,TRUE),IF($C44="DUCTED-INV",VLOOKUP($E44,'DX-Data'!$D$12:$J$18,7,TRUE),"CHOOSE AC TYPE"))))) -> FDMRN20AVKU - RR20AVKU | AH44: =IF($F$9=TRUE,IF($C44="DUCTED",VLOOKUP($F44,'DX-Data'!$F$5:$J$11,5,TRUE),IF($C44="DECORATIVE",VLOOKUP($F44,'DX-Data'!$F$19:$J$23,5,TRUE),IF($C44="PACKAGED",VLOOKUP($F44,'DX-Data'!$F$24:$J$30,5,TRUE),IF($C44="DUCTED-INV",VLOOKUP($F44,'DX-Data'!$F$12:$J$18,5,TRUE),"CHOOSE AC TYPE")))),"NO SELECTION") -> FDMRN20AVKU - RR20AVKU | AI44: =IF($G$9=TRUE,IF($C44="DUCTED",VLOOKUP($G44,'DX-Data'!$H$5:$J$11,3,TRUE),IF($C44="DECORATIVE",VLOOKUP($G44,'DX-Data'!$H$19:$J$23,3,TRUE),IF($C44="PACKAGED",VLOOKUP($G44,'DX-Data'!$H$24:$J$30,3,TRUE),IF($C44="DUCTED-INV",VLOOKUP($G44,'DX-Data'!$H$12:$J$18,3,TRUE),"CHOOSE AC TYPE")))),"NO SELECTION") -> NO SELECTION | AJ44: =IF($E44="","",IF($C44="DUCTED",VLOOKUP($E44,'DX-Data'!$D$5:$J$11,6,TRUE),IF($C44="DECORATIVE",VLOOKUP($E44,'DX-Data'!$D$19:$J$23,6,TRUE),IF($C44="PACKAGED",VLOOKUP($E44,'DX-Data'!$D$24:$J$30,6,TRUE),IF($C44="DUCTED-INV",VLOOKUP($E44,'DX-Data'!$D$12:$J$18,6,TRUE),0))))) -> 1 | AK44: =IF($F$9=TRUE,IF($C44="DUCTED",VLOOKUP($F44,'DX-Data'!$F$5:$J$11,4,TRUE),IF($C44="DECORATIVE",VLOOKUP($F44,'DX-Data'!$F$19:$J$23,4,TRUE),IF($C44="PACKAGED",VLOOKUP($F44,'DX-Data'!$F$24:$J$30,4,TRUE),IF($C44="DUCTED-INV",VLOOKUP($F44,'DX-Data'!$F$12:$J$18,4,TRUE),"CHOOSE AC TYPE")))),0) -> 1 | AL44: =IF($G$9=TRUE,IF($C44="DUCTED",VLOOKUP($G44,'DX-Data'!$H$5:$J$11,2,TRUE),IF($C44="DECORATIVE",VLOOKUP($G44,'DX-Data'!$H$19:$J$23,2,TRUE),IF($C44="PACKAGED",VLOOKUP($G44,'DX-Data'!$H$24:$J$30,2,TRUE),IF($C44="DUCTED-INV",VLOOKUP($G44,'DX-Data'!$H$12:$J$18,2,TRUE),"CHOOSE AC TYPE")))),0) -> 0 | AM44: =MAX(AJ44:AL44) -> 1 | AN44: =IF(E44="","",VLOOKUP($AM44,'DX-Data'!$I$5:$J$31,2,FALSE)) -> FDMRN20AVKU - RR20AVKU | AO44: =IF(OR(AN44="",AN44=0),"",1) -> 1
