Workbook

Sheet VRV Schedule
B4: Project: | C4: {Project_Name}
B5: HVAC Contr: | C5: {Customer_Name}
B6: VRV Schedule
B7: SPECIFIED | H7: PROPOSED INDOOR UNITS | V7: PROPOSED OUTDOOR UNITS
B8: System | C8: Name | D8: Location | E8: Rq TC | F8: Rq SC | G8: Air Flow Rate | H8: FCU | I8: Nominal Index | J8: Country of Origin | K8: Type | L8: Ambient - On Coil Temperature | M8: Max TC | N8: Max SC | O8: Air Flow Rate | P8: PIC | Q8: Sound | R8: PS | S8: MCA | T8: WxHxD | U8: Weight | V8: Name | W8: Model | X8: Nominal index | Y8: Cooling | AA8: CR | AB8: PI ESMA | AC8: PS | AD8: MCA | AE8: MOP | AF8: RLA | AG8: WxHxD | AH8: Weight
E9: kW | F9: kW | G9: l/s | L9: °C | M9: kW | N9: kW | O9: l/s | P9: kW | Q9: dBA | S9: A | T9: mm | U9: kg | Y9: Ambient Temp | Z9: CC | AD9: A | AE9: A | AF9: A | AG9: mm | AH9: kg
L10: (DBT/WBT) | Y10: °C | Z10: kw | AB10: kw
B11: VRV-GF | C11: GF-01 | D11: BEDROOM 01 | E11: 3.8 | F11: 3 | G11: 198 | H11: FXMQ40PBV1 | I11: =IF($H11="","",VLOOKUP($H11,'Indoor Data'!$B$6:$O$57,13,FALSE)) -> 40 | J11: =IF($H11="","",VLOOKUP($H11,'Indoor Data'!$B$6:$O$57,14,FALSE)) -> India | K11: =IF($H11="","",VLOOKUP($H11,'Indoor Data'!$B$6:$O$57,2,FALSE)) -> Ducted | L11: =IF($H11="","",VLOOKUP($H11,'Indoor Data'!$B$6:$O$57,3,FALSE)) -> 46 - 24.4/17.2 | M11: =IF($H11="","",VLOOKUP($H11,'Indoor Data'!$B$6:$O$57,4,FALSE)) -> 4 | N11: =IF($H11="","",VLOOKUP($H11,'Indoor Data'!$B$6:$O$57,5,FALSE)) -> 3.5 | O11: =IF($H11="","",VLOOKUP($H11,'Indoor Data'!$B$6:$O$57,6,FALSE)) -> 266.67 | P11: =IF($H11="","",VLOOKUP($H11,'Indoor Data'!$B$6:$O$57,7,FALSE)) -> 0.151 | Q11: =IF($H11="","",VLOOKUP($H11,'Indoor Data'!$B$6:$O$57,8,FALSE)) -> 35 - 39 | R11: =IF($H11="","",VLOOKUP($H11,'Indoor Data'!$B$6:$O$57,9,FALSE)) -> 230V 1ph | S11: =IF($H11="","",VLOOKUP($H11,'Indoor Data'!$B$6:$O$57,10,FALSE)) -> 1.4 | T11: =IF($H11="","",VLOOKUP($H11,'Indoor Data'!$B$6:$O$57,11,FALSE)) -> 700 x 300 x 700 | U11: =IF($H11="","",VLOOKUP($H11,'Indoor Data'!$B$6:$O$57,12,FALSE)) -> 27
C12: GF-02 | D12: BEDROOM 02 | E12: 4.1 | F12: 3.1 | G12: 207 | H12: FXMQ50PBV1 | I12: =IF($H12="","",VLOOKUP($H12,'Indoor Data'!$B$6:$O$57,13,FALSE)) -> 50 | J12: =IF($H12="","",VLOOKUP($H12,'Indoor Data'!$B$6:$O$57,14,FALSE)) -> India | K12: =IF($H12="","",VLOOKUP($H12,'Indoor Data'!$B$6:$O$57,2,FALSE)) -> Ducted | L12: =IF($H12="","",VLOOKUP($H12,'Indoor Data'!$B$6:$O$57,3,FALSE)) -> 46 - 24.4/17.2 | M12: =IF($H12="","",VLOOKUP($H12,'Indoor Data'!$B$6:$O$57,4,FALSE)) -> 4.9 | N12: =IF($H12="","",VLOOKUP($H12,'Indoor Data'!$B$6:$O$57,5,FALSE)) -> 4.2 | O12: =IF($H12="","",VLOOKUP($H12,'Indoor Data'!$B$6:$O$57,6,FALSE)) -> 300 | P12: =IF($H12="","",VLOOKUP($H12,'Indoor Data'!$B$6:$O$57,7,FALSE)) -> 0.128 | Q12: =IF($H12="","",VLOOKUP($H12,'Indoor Data'!$B$6:$O$57,8,FALSE)) -> 37 - 41 | R12: =IF($H12="","",VLOOKUP($H12,'Indoor Data'!$B$6:$O$57,9,FALSE)) -> 230V 1ph | S12: =IF($H12="","",VLOOKUP($H12,'Indoor Data'!$B$6:$O$57,10,FALSE)) -> 1.6 | T12: =IF($H12="","",VLOOKUP($H12,'Indoor Data'!$B$6:$O$57,11,FALSE)) -> 1,000 x 300 x 700 | U12: =IF($H12="","",VLOOKUP($H12,'Indoor Data'!$B$6:$O$57,12,FALSE)) -> 35 | X12: =IF($W12="",0,VLOOKUP($W12,'Outdoor Data'!$B$6:$L$16,11,FALSE)) -> 0 | Y12: =IF($W12="","",VLOOKUP($W12,'Outdoor Data'!$B$6:$L$16,2,FALSE)) | Z12: =IF($W12="","",VLOOKUP($W12,'Outdoor Data'!$B$6:$L$16,3,FALSE)) | AA12: =IF(W12="","",I26/X26) | AB12: =IF($W12="","",VLOOKUP($W12,'Outdoor Data'!$B$6:$L$16,4,FALSE)) | AC12: =IF($W12="","",VLOOKUP($W12,'Outdoor Data'!$B$6:$L$16,5,FALSE)) | AD12: =IF($W12="","",VLOOKUP($W12,'Outdoor Data'!$B$6:$L$16,6,FALSE)) | AE12: =IF($W12="","",VLOOKUP($W12,'Outdoor Data'!$B$6:$L$16,7,FALSE)) | AF12: =IF($W12="","",VLOOKUP($W12,'Outdoor Data'!$B$6:$L$16,8,FALSE)) | AG12: =IF($W12="","",VLOOKUP($W12,'Outdoor Data'!$B$6:$L$16,9,FALSE)) | AH12: =IF($W12="","",VLOOKUP($W12,'Outdoor Data'!$B$6:$L$16,10,FALSE))
C13: GF-03 | D13: BEDROOM 03 | E13: 4.1 | F13: 3.1 | G13: 210 | H13: FXMQ50PBV1 | I13: =IF($H13="","",VLOOKUP($H13,'Indoor Data'!$B$6:$O$57,13,FALSE)) -> 50 | J13: =IF($H13="","",VLOOKUP($H13,'Indoor Data'!$B$6:$O$57,14,FALSE)) -> India | K13: =IF($H13="","",VLOOKUP($H13,'Indoor Data'!$B$6:$O$57,2,FALSE)) -> Ducted | L13: =IF($H13="","",VLOOKUP($H13,'Indoor Data'!$B$6:$O$57,3,FALSE)) -> 46 - 24.4/17.2 | M13: =IF($H13="","",VLOOKUP($H13,'Indoor Data'!$B$6:$O$57,4,FALSE)) -> 4.9 | N13: =IF($H13="","",VLOOKUP($H13,'Indoor Data'!$B$6:$O$57,5,FALSE)) -> 4.2 | O13: =IF($H13="","",VLOOKUP($H13,'Indoor Data'!$B$6:$O$57,6,FALSE)) -> 300 | P13: =IF($H13="","",VLOOKUP($H13,'Indoor Data'!$B$6:$O$57,7,FALSE)) -> 0.128 | Q13: =IF($H13="","",VLOOKUP($H13,'Indoor Data'!$B$6:$O$57,8,FALSE)) -> 37 - 41 | R13: =IF($H13="","",VLOOKUP($H13,'Indoor Data'!$B$6:$O$57,9,FALSE)) -> 230V 1ph | S13: =IF($H13="","",VLOOKUP($H13,'Indoor Data'!$B$6:$O$57,10,FALSE)) -> 1.6 | T13: =IF($H13="","",VLOOKUP($H13,'Indoor Data'!$B$6:$O$57,11,FALSE)) -> 1,000 x 300 x 700 | U13: =IF($H13="","",VLOOKUP($H13,'Indoor Data'!$B$6:$O$57,12,FALSE)) -> 35 | V13: VRV-GF | W13: RXQ18ANRYFK | Y13: 46 | Z13: 40.4 | AA13: =IF(W14="","",I26/X26) -> 1.0733333 | AJ13: Expected CR | AK13: 1.1
C14: GF-04 | D14: BEDROOM 04 | E14: 4.1 | F14: 3.1 | G14: 210 | H14: FXMQ50PBV1 | I14: =IF($H14="","",VLOOKUP($H14,'Indoor Data'!$B$6:$O$57,13,FALSE)) -> 50 | J14: =IF($H14="","",VLOOKUP($H14,'Indoor Data'!$B$6:$O$57,14,FALSE)) -> India | K14: =IF($H14="","",VLOOKUP($H14,'Indoor Data'!$B$6:$O$57,2,FALSE)) -> Ducted | L14: =IF($H14="","",VLOOKUP($H14,'Indoor Data'!$B$6:$O$57,3,FALSE)) -> 46 - 24.4/17.2 | M14: =IF($H14="","",VLOOKUP($H14,'Indoor Data'!$B$6:$O$57,4,FALSE)) -> 4.9 | N14: =IF($H14="","",VLOOKUP($H14,'Indoor Data'!$B$6:$O$57,5,FALSE)) -> 4.2 | O14: =IF($H14="","",VLOOKUP($H14,'Indoor Data'!$B$6:$O$57,6,FALSE)) -> 300 | P14: =IF($H14="","",VLOOKUP($H14,'Indoor Data'!$B$6:$O$57,7,FALSE)) -> 0.128 | Q14: =IF($H14="","",VLOOKUP($H14,'Indoor Data'!$B$6:$O$57,8,FALSE)) -> 37 - 41 | R14: =IF($H14="","",VLOOKUP($H14,'Indoor Data'!$B$6:$O$57,9,FALSE)) -> 230V 1ph | S14: =IF($H14="","",VLOOKUP($H14,'Indoor Data'!$B$6:$O$57,10,FALSE)) -> 1.6 | T14: =IF($H14="","",VLOOKUP($H14,'Indoor Data'!$B$6:$O$57,11,FALSE)) -> 1,000 x 300 x 700 | U14: =IF($H14="","",VLOOKUP($H14,'Indoor Data'!$B$6:$O$57,12,FALSE)) -> 35 | V14: A | W14: RXQ12ARYFK | X14: =IF($W14="",0,VLOOKUP($W14,'Outdoor Data'!$B$6:$L$16,11,FALSE)) -> 300 | AB14: =IF($W14="","",VLOOKUP($W14,'Outdoor Data'!$B$6:$L$16,4,FALSE)) -> 10.4 | AC14: =IF($W14="","",VLOOKUP($W14,'Outdoor Data'!$B$6:$L$16,5,FALSE)) -> 400V 3Nph | AD14: =IF($W14="","",VLOOKUP($W14,'Outdoor Data'!$B$6:$L$16,6,FALSE)) -> 26.9 | AE14: =IF($W14="","",VLOOKUP($W14,'Outdoor Data'!$B$6:$L$16,7,FALSE)) -> - | AF14: =IF($W14="","",VLOOKUP($W14,'Outdoor Data'!$B$6:$L$16,8,FALSE)) -> - | AG14: =IF($W14="","",VLOOKUP($W14,'Outdoor Data'!$B$6:$L$16,9,FALSE)) -> 1,240 x 1,657 x 765 | AH14: =IF($W14="","",VLOOKUP($W14,'Outdoor Data'!$B$6:$L$16,10,FALSE)) -> 220 | AJ14: Required ODU | AK14: =(I26/AK13)/25 -> 17.563636 | AL14: hp
C15: GF-05 | D15: BEDROOM 05 | E15: 4.3 | F15: 3.3 | G15: 227 | H15: FXMQ50PBV1 | I15: =IF($H15="","",VLOOKUP($H15,'Indoor Data'!$B$6:$O$57,13,FALSE)) -> 50 | J15: =IF($H15="","",VLOOKUP($H15,'Indoor Data'!$B$6:$O$57,14,FALSE)) -> India | K15: =IF($H15="","",VLOOKUP($H15,'Indoor Data'!$B$6:$O$57,2,FALSE)) -> Ducted | L15: =IF($H15="","",VLOOKUP($H15,'Indoor Data'!$B$6:$O$57,3,FALSE)) -> 46 - 24.4/17.2 | M15: =IF($H15="","",VLOOKUP($H15,'Indoor Data'!$B$6:$O$57,4,FALSE)) -> 4.9 | N15: =IF($H15="","",VLOOKUP($H15,'Indoor Data'!$B$6:$O$57,5,FALSE)) -> 4.2 | O15: =IF($H15="","",VLOOKUP($H15,'Indoor Data'!$B$6:$O$57,6,FALSE)) -> 300 | P15: =IF($H15="","",VLOOKUP($H15,'Indoor Data'!$B$6:$O$57,7,FALSE)) -> 0.128 | Q15: =IF($H15="","",VLOOKUP($H15,'Indoor Data'!$B$6:$O$57,8,FALSE)) -> 37 - 41 | R15: =IF($H15="","",VLOOKUP($H15,'Indoor Data'!$B$6:$O$57,9,FALSE)) -> 230V 1ph | S15: =IF($H15="","",VLOOKUP($H15,'Indoor Data'!$B$6:$O$57,10,FALSE)) -> 1.6 | T15: =IF($H15="","",VLOOKUP($H15,'Indoor Data'!$B$6:$O$57,11,FALSE)) -> 1,000 x 300 x 700 | U15: =IF($H15="","",VLOOKUP($H15,'Indoor Data'!$B$6:$O$57,12,FALSE)) -> 35 | V15: B | W15: RXQ6ARYFK | X15: =IF($W15="",0,VLOOKUP($W15,'Outdoor Data'!$B$6:$L$16,11,FALSE)) -> 150 | AB15: =IF($W15="","",VLOOKUP($W15,'Outdoor Data'!$B$6:$L$16,4,FALSE)) -> 5.1 | AC15: =IF($W15="","",VLOOKUP($W15,'Outdoor Data'!$B$6:$L$16,5,FALSE)) -> 400V 3Nph | AD15: =IF($W15="","",VLOOKUP($W15,'Outdoor Data'!$B$6:$L$16,6,FALSE)) -> 16.1 | AE15: =IF($W15="","",VLOOKUP($W15,'Outdoor Data'!$B$6:$L$16,7,FALSE)) -> - | AF15: =IF($W15="","",VLOOKUP($W15,'Outdoor Data'!$B$6:$L$16,8,FALSE)) -> - | AG15: =IF($W15="","",VLOOKUP($W15,'Outdoor Data'!$B$6:$L$16,9,FALSE)) -> 930 x 1,657 x 765 | AH15: =IF($W15="","",VLOOKUP($W15,'Outdoor Data'!$B$6:$L$16,10,FALSE)) -> 165
C16: GF-06 | D16: MAIDS ROOM | E16: 2.9 | F16: 2.2 | G16: 138 | H16: FXMQ40PBV1 | I16: =IF($H16="","",VLOOKUP($H16,'Indoor Data'!$B$6:$O$57,13,FALSE)) -> 40 | J16: =IF($H16="","",VLOOKUP($H16,'Indoor Data'!$B$6:$O$57,14,FALSE)) -> India | K16: =IF($H16="","",VLOOKUP($H16,'Indoor Data'!$B$6:$O$57,2,FALSE)) -> Ducted | L16: =IF($H16="","",VLOOKUP($H16,'Indoor Data'!$B$6:$O$57,3,FALSE)) -> 46 - 24.4/17.2 | M16: =IF($H16="","",VLOOKUP($H16,'Indoor Data'!$B$6:$O$57,4,FALSE)) -> 4 | N16: =IF($H16="","",VLOOKUP($H16,'Indoor Data'!$B$6:$O$57,5,FALSE)) -> 3.5 | O16: =IF($H16="","",VLOOKUP($H16,'Indoor Data'!$B$6:$O$57,6,FALSE)) -> 266.67 | P16: =IF($H16="","",VLOOKUP($H16,'Indoor Data'!$B$6:$O$57,7,FALSE)) -> 0.151 | Q16: =IF($H16="","",VLOOKUP($H16,'Indoor Data'!$B$6:$O$57,8,FALSE)) -> 35 - 39 | R16: =IF($H16="","",VLOOKUP($H16,'Indoor Data'!$B$6:$O$57,9,FALSE)) -> 230V 1ph | S16: =IF($H16="","",VLOOKUP($H16,'Indoor Data'!$B$6:$O$57,10,FALSE)) -> 1.4 | T16: =IF($H16="","",VLOOKUP($H16,'Indoor Data'!$B$6:$O$57,11,FALSE)) -> 700 x 300 x 700 | U16: =IF($H16="","",VLOOKUP($H16,'Indoor Data'!$B$6:$O$57,12,FALSE)) -> 27 | X16: =IF($W16="",0,VLOOKUP($W16,'Outdoor Data'!$B$6:$L$16,11,FALSE)) -> 0 | AB16: =IF($W16="","",VLOOKUP($W16,'Outdoor Data'!$B$6:$L$16,4,FALSE)) | AC16: =IF($W16="","",VLOOKUP($W16,'Outdoor Data'!$B$6:$L$16,5,FALSE)) | AD16: =IF($W16="","",VLOOKUP($W16,'Outdoor Data'!$B$6:$L$16,6,FALSE)) | AE16: =IF($W16="","",VLOOKUP($W16,'Outdoor Data'!$B$6:$L$16,7,FALSE)) | AF16: =IF($W16="","",VLOOKUP($W16,'Outdoor Data'!$B$6:$L$16,8,FALSE)) | AG16: =IF($W16="","",VLOOKUP($W16,'Outdoor Data'!$B$6:$L$16,9,FALSE)) | AH16: =IF($W16="","",VLOOKUP($W16,'Outdoor Data'!$B$6:$L$16,10,FALSE))
C17: GF-07 | D17: KITCHEN | E17: 3.6 | F17: 2.7 | G17: 177 | H17: FXMQ40PBV1 | I17: =IF($H17="","",VLOOKUP($H17,'Indoor Data'!$B$6:$O$57,13,FALSE)) -> 40 | J17: =IF($H17="","",VLOOKUP($H17,'Indoor Data'!$B$6:$O$57,14,FALSE)) -> India | K17: =IF($H17="","",VLOOKUP($H17,'Indoor Data'!$B$6:$O$57,2,FALSE)) -> Ducted | L17: =IF($H17="","",VLOOKUP($H17,'Indoor Data'!$B$6:$O$57,3,FALSE)) -> 46 - 24.4/17.2 | M17: =IF($H17="","",VLOOKUP($H17,'Indoor Data'!$B$6:$O$57,4,FALSE)) -> 4 | N17: =IF($H17="","",VLOOKUP($H17,'Indoor Data'!$B$6:$O$57,5,FALSE)) -> 3.5 | O17: =IF($H17="","",VLOOKUP($H17,'Indoor Data'!$B$6:$O$57,6,FALSE)) -> 266.67 | P17: =IF($H17="","",VLOOKUP($H17,'Indoor Data'!$B$6:$O$57,7,FALSE)) -> 0.151 | Q17: =IF($H17="","",VLOOKUP($H17,'Indoor Data'!$B$6:$O$57,8,FALSE)) -> 35 - 39 | R17: =IF($H17="","",VLOOKUP($H17,'Indoor Data'!$B$6:$O$57,9,FALSE)) -> 230V 1ph | S17: =IF($H17="","",VLOOKUP($H17,'Indoor Data'!$B$6:$O$57,10,FALSE)) -> 1.4 | T17: =IF($H17="","",VLOOKUP($H17,'Indoor Data'!$B$6:$O$57,11,FALSE)) -> 700 x 300 x 700 | U17: =IF($H17="","",VLOOKUP($H17,'Indoor Data'!$B$6:$O$57,12,FALSE)) -> 27
C18: GF-08 | D18: STORE 1,2 / LIFT LOBBY 01 | E18: 8.1 | F18: 6.3 | G18: 429 | H18: FXMQ100PBV1 | I18: =IF($H18="","",VLOOKUP($H18,'Indoor Data'!$B$6:$O$57,13,FALSE)) -> 100 | J18: =IF($H18="","",VLOOKUP($H18,'Indoor Data'!$B$6:$O$57,14,FALSE)) -> India | K18: =IF($H18="","",VLOOKUP($H18,'Indoor Data'!$B$6:$O$57,2,FALSE)) -> Ducted | L18: =IF($H18="","",VLOOKUP($H18,'Indoor Data'!$B$6:$O$57,3,FALSE)) -> 46 - 24.4/17.2 | M18: =IF($H18="","",VLOOKUP($H18,'Indoor Data'!$B$6:$O$57,4,FALSE)) -> 9.9 | N18: =IF($H18="","",VLOOKUP($H18,'Indoor Data'!$B$6:$O$57,5,FALSE)) -> 7.7 | O18: =IF($H18="","",VLOOKUP($H18,'Indoor Data'!$B$6:$O$57,6,FALSE)) -> 533.33 | P18: =IF($H18="","",VLOOKUP($H18,'Indoor Data'!$B$6:$O$57,7,FALSE)) -> 0.215 | Q18: =IF($H18="","",VLOOKUP($H18,'Indoor Data'!$B$6:$O$57,8,FALSE)) -> 39 - 43 | R18: =IF($H18="","",VLOOKUP($H18,'Indoor Data'!$B$6:$O$57,9,FALSE)) -> 230V 1ph | S18: =IF($H18="","",VLOOKUP($H18,'Indoor Data'!$B$6:$O$57,10,FALSE)) -> 2.9 | T18: =IF($H18="","",VLOOKUP($H18,'Indoor Data'!$B$6:$O$57,11,FALSE)) -> 1,400 x 300 x 700 | U18: =IF($H18="","",VLOOKUP($H18,'Indoor Data'!$B$6:$O$57,12,FALSE)) -> 45
C19: GF-10 | D19: CORRIDOR / LIFT LOBBY 02 | E19: 6 | F19: 4.7 | G19: 318 | H19: FXMQ63PBV1 | I19: =IF($H19="","",VLOOKUP($H19,'Indoor Data'!$B$6:$O$57,13,FALSE)) -> 63 | J19: =IF($H19="","",VLOOKUP($H19,'Indoor Data'!$B$6:$O$57,14,FALSE)) -> India | K19: =IF($H19="","",VLOOKUP($H19,'Indoor Data'!$B$6:$O$57,2,FALSE)) -> Ducted | L19: =IF($H19="","",VLOOKUP($H19,'Indoor Data'!$B$6:$O$57,3,FALSE)) -> 46 - 24.4/17.2 | M19: =IF($H19="","",VLOOKUP($H19,'Indoor Data'!$B$6:$O$57,4,FALSE)) -> 6.2 | N19: =IF($H19="","",VLOOKUP($H19,'Indoor Data'!$B$6:$O$57,5,FALSE)) -> 5.1 | O19: =IF($H19="","",VLOOKUP($H19,'Indoor Data'!$B$6:$O$57,6,FALSE)) -> 325 | P19: =IF($H19="","",VLOOKUP($H19,'Indoor Data'!$B$6:$O$57,7,FALSE)) -> 0.138 | Q19: =IF($H19="","",VLOOKUP($H19,'Indoor Data'!$B$6:$O$57,8,FALSE)) -> 38 - 42 | R19: =IF($H19="","",VLOOKUP($H19,'Indoor Data'!$B$6:$O$57,9,FALSE)) -> 230V 1ph | S19: =IF($H19="","",VLOOKUP($H19,'Indoor Data'!$B$6:$O$57,10,FALSE)) -> 1.8 | T19: =IF($H19="","",VLOOKUP($H19,'Indoor Data'!$B$6:$O$57,11,FALSE)) -> 1,000 x 300 x 700 | U19: =IF($H19="","",VLOOKUP($H19,'Indoor Data'!$B$6:$O$57,12,FALSE)) -> 35
I20: =IF($H20="","",VLOOKUP($H20,'Indoor Data'!$B$6:$O$57,13,FALSE)) | J20: =IF($H20="","",VLOOKUP($H20,'Indoor Data'!$B$6:$O$57,14,FALSE)) | K20: =IF($H20="","",VLOOKUP($H20,'Indoor Data'!$B$6:$O$57,2,FALSE)) | L20: =IF($H20="","",VLOOKUP($H20,'Indoor Data'!$B$6:$O$57,3,FALSE)) | M20: =IF($H20="","",VLOOKUP($H20,'Indoor Data'!$B$6:$O$57,4,FALSE)) | N20: =IF($H20="","",VLOOKUP($H20,'Indoor Data'!$B$6:$O$57,5,FALSE)) | O20: =IF($H20="","",VLOOKUP($H20,'Indoor Data'!$B$6:$O$57,6,FALSE)) | P20: =IF($H20="","",VLOOKUP($H20,'Indoor Data'!$B$6:$O$57,7,FALSE)) | Q20: =IF($H20="","",VLOOKUP($H20,'Indoor Data'!$B$6:$O$57,8,FALSE)) | R20: =IF($H20="","",VLOOKUP($H20,'Indoor Data'!$B$6:$O$57,9,FALSE)) | S20: =IF($H20="","",VLOOKUP($H20,'Indoor Data'!$B$6:$O$57,10,FALSE)) | T20: =IF($H20="","",VLOOKUP($H20,'Indoor Data'!$B$6:$O$57,11,FALSE)) | U20: =IF($H20="","",VLOOKUP($H20,'Indoor Data'!$B$6:$O$57,12,FALSE))
I21: =IF($H21="","",VLOOKUP($H21,'Indoor Data'!$B$6:$O$57,13,FALSE)) | J21: =IF($H21="","",VLOOKUP($H21,'Indoor Data'!$B$6:$O$57,14,FALSE)) | K21: =IF($H21="","",VLOOKUP($H21,'Indoor Data'!$B$6:$O$57,2,FALSE)) | L21: =IF($H21="","",VLOOKUP($H21,'Indoor Data'!$B$6:$O$57,3,FALSE)) | M21: =IF($H21="","",VLOOKUP($H21,'Indoor Data'!$B$6:$O$57,4,FALSE)) | N21: =IF($H21="","",VLOOKUP($H21,'Indoor Data'!$B$6:$O$57,5,FALSE)) | O21: =IF($H21="","",VLOOKUP($H21,'Indoor Data'!$B$6:$O$57,6,FALSE)) | P21: =IF($H21="","",VLOOKUP($H21,'Indoor Data'!$B$6:$O$57,7,FALSE)) | Q21: =IF($H21="","",VLOOKUP($H21,'Indoor Data'!$B$6:$O$57,8,FALSE)) | R21: =IF($H21="","",VLOOKUP($H21,'Indoor Data'!$B$6:$O$57,9,FALSE)) | S21: =IF($H21="","",VLOOKUP($H21,'Indoor Data'!$B$6:$O$57,10,FALSE)) | T21: =IF($H21="","",VLOOKUP($H21,'Indoor Data'!$B$6:$O$57,11,FALSE)) | U21: =IF($H21="","",VLOOKUP($H21,'Indoor Data'!$B$6:$O$57,12,FALSE))
I22: =IF($H22="","",VLOOKUP($H22,'Indoor Data'!$B$6:$O$57,13,FALSE)) | J22: =IF($H22="","",VLOOKUP($H22,'Indoor Data'!$B$6:$O$57,14,FALSE)) | K22: =IF($H22="","",VLOOKUP($H22,'Indoor Data'!$B$6:$O$57,2,FALSE)) | L22: =IF($H22="","",VLOOKUP($H22,'Indoor Data'!$B$6:$O$57,3,FALSE)) | M22: =IF($H22="","",VLOOKUP($H22,'Indoor Data'!$B$6:$O$57,4,FALSE)) | N22: =IF($H22="","",VLOOKUP($H22,'Indoor Data'!$B$6:$O$57,5,FALSE)) | O22: =IF($H22="","",VLOOKUP($H22,'Indoor Data'!$B$6:$O$57,6,FALSE)) | P22: =IF($H22="","",VLOOKUP($H22,'Indoor Data'!$B$6:$O$57,7,FALSE)) | Q22: =IF($H22="","",VLOOKUP($H22,'Indoor Data'!$B$6:$O$57,8,FALSE)) | R22: =IF($H22="","",VLOOKUP($H22,'Indoor Data'!$B$6:$O$57,9,FALSE)) | S22: =IF($H22="","",VLOOKUP($H22,'Indoor Data'!$B$6:$O$57,10,FALSE)) | T22: =IF($H22="","",VLOOKUP($H22,'Indoor Data'!$B$6:$O$57,11,FALSE)) | U22: =IF($H22="","",VLOOKUP($H22,'Indoor Data'!$B$6:$O$57,12,FALSE))
I23: =IF($H23="","",VLOOKUP($H23,'Indoor Data'!$B$6:$O$57,13,FALSE)) | J23: =IF($H23="","",VLOOKUP($H23,'Indoor Data'!$B$6:$O$57,14,FALSE)) | K23: =IF($H23="","",VLOOKUP($H23,'Indoor Data'!$B$6:$O$57,2,FALSE)) | L23: =IF($H23="","",VLOOKUP($H23,'Indoor Data'!$B$6:$O$57,3,FALSE)) | M23: =IF($H23="","",VLOOKUP($H23,'Indoor Data'!$B$6:$O$57,4,FALSE)) | N23: =IF($H23="","",VLOOKUP($H23,'Indoor Data'!$B$6:$O$57,5,FALSE)) | O23: =IF($H23="","",VLOOKUP($H23,'Indoor Data'!$B$6:$O$57,6,FALSE)) | P23: =IF($H23="","",VLOOKUP($H23,'Indoor Data'!$B$6:$O$57,7,FALSE)) | Q23: =IF($H23="","",VLOOKUP($H23,'Indoor Data'!$B$6:$O$57,8,FALSE)) | R23: =IF($H23="","",VLOOKUP($H23,'Indoor Data'!$B$6:$O$57,9,FALSE)) | S23: =IF($H23="","",VLOOKUP($H23,'Indoor Data'!$B$6:$O$57,10,FALSE)) | T23: =IF($H23="","",VLOOKUP($H23,'Indoor Data'!$B$6:$O$57,11,FALSE)) | U23: =IF($H23="","",VLOOKUP($H23,'Indoor Data'!$B$6:$O$57,12,FALSE))
I24: =IF($H24="","",VLOOKUP($H24,'Indoor Data'!$B$6:$O$57,13,FALSE)) | J24: =IF($H24="","",VLOOKUP($H24,'Indoor Data'!$B$6:$O$57,14,FALSE)) | K24: =IF($H24="","",VLOOKUP($H24,'Indoor Data'!$B$6:$O$57,2,FALSE)) | L24: =IF($H24="","",VLOOKUP($H24,'Indoor Data'!$B$6:$O$57,3,FALSE)) | M24: =IF($H24="","",VLOOKUP($H24,'Indoor Data'!$B$6:$O$57,4,FALSE)) | N24: =IF($H24="","",VLOOKUP($H24,'Indoor Data'!$B$6:$O$57,5,FALSE)) | O24: =IF($H24="","",VLOOKUP($H24,'Indoor Data'!$B$6:$O$57,6,FALSE)) | P24: =IF($H24="","",VLOOKUP($H24,'Indoor Data'!$B$6:$O$57,7,FALSE)) | Q24: =IF($H24="","",VLOOKUP($H24,'Indoor Data'!$B$6:$O$57,8,FALSE)) | R24: =IF($H24="","",VLOOKUP($H24,'Indoor Data'!$B$6:$O$57,9,FALSE)) | S24: =IF($H24="","",VLOOKUP($H24,'Indoor Data'!$B$6:$O$57,10,FALSE)) | T24: =IF($H24="","",VLOOKUP($H24,'Indoor Data'!$B$6:$O$57,11,FALSE)) | U24: =IF($H24="","",VLOOKUP($H24,'Indoor Data'!$B$6:$O$57,12,FALSE))
I25: =IF($H25="","",VLOOKUP($H25,'Indoor Data'!$B$6:$O$57,13,FALSE)) | J25: =IF($H25="","",VLOOKUP($H25,'Indoor Data'!$B$6:$O$57,14,FALSE)) | K25: =IF($H25="","",VLOOKUP($H25,'Indoor Data'!$B$6:$O$57,2,FALSE)) | L25: =IF($H25="","",VLOOKUP($H25,'Indoor Data'!$B$6:$O$57,3,FALSE)) | M25: =IF($H25="","",VLOOKUP($H25,'Indoor Data'!$B$6:$O$57,4,FALSE)) | N25: =IF($H25="","",VLOOKUP($H25,'Indoor Data'!$B$6:$O$57,5,FALSE)) | O25: =IF($H25="","",VLOOKUP($H25,'Indoor Data'!$B$6:$O$57,6,FALSE)) | P25: =IF($H25="","",VLOOKUP($H25,'Indoor Data'!$B$6:$O$57,7,FALSE)) | Q25: =IF($H25="","",VLOOKUP($H25,'Indoor Data'!$B$6:$O$57,8,FALSE)) | R25: =IF($H25="","",VLOOKUP($H25,'Indoor Data'!$B$6:$O$57,9,FALSE)) | S25: =IF($H25="","",VLOOKUP($H25,'Indoor Data'!$B$6:$O$57,10,FALSE)) | T25: =IF($H25="","",VLOOKUP($H25,'Indoor Data'!$B$6:$O$57,11,FALSE)) | U25: =IF($H25="","",VLOOKUP($H25,'Indoor Data'!$B$6:$O$57,12,FALSE))
E26: =SUM(E11:E25) -> 41 | F26: =SUM(F11:F25) -> 31.5 | G26: =SUM(G11:G25) -> 2114 | I26: =SUM(I11:I25) -> 483 | M26: =SUM(M11:M25) -> 47.7 | N26: =SUM(N11:N25) -> 40.1 | O26: =SUM(O11:O25) -> 2858.34 | P26: =SUM(P11:P25) -> 1.318 | X26: =X16+X15+X14+X12 -> 450 | AB26: =SUM(AB11:AB25) -> 15.5
B28: VRV-FF | C28: FF-01 | D28: KIDS ROOM | E28: 5 | F28: 3.8 | G28: 249 | H28: FXMQ63PBV1 | I28: =IF($H28="","",VLOOKUP($H28,'Indoor Data'!$B$6:$O$57,13,FALSE)) -> 63 | J28: =IF($H28="","",VLOOKUP($H28,'Indoor Data'!$B$6:$O$57,14,FALSE)) -> India | K28: =IF($H28="","",VLOOKUP($H28,'Indoor Data'!$B$6:$O$57,2,FALSE)) -> Ducted | L28: =IF($H28="","",VLOOKUP($H28,'Indoor Data'!$B$6:$O$57,3,FALSE)) -> 46 - 24.4/17.2 | M28: =IF($H28="","",VLOOKUP($H28,'Indoor Data'!$B$6:$O$57,4,FALSE)) -> 6.2 | N28: =IF($H28="","",VLOOKUP($H28,'Indoor Data'!$B$6:$O$57,5,FALSE)) -> 5.1 | O28: =IF($H28="","",VLOOKUP($H28,'Indoor Data'!$B$6:$O$57,6,FALSE)) -> 325 | P28: =IF($H28="","",VLOOKUP($H28,'Indoor Data'!$B$6:$O$57,7,FALSE)) -> 0.138 | Q28: =IF($H28="","",VLOOKUP($H28,'Indoor Data'!$B$6:$O$57,8,FALSE)) -> 38 - 42 | R28: =IF($H28="","",VLOOKUP($H28,'Indoor Data'!$B$6:$O$57,9,FALSE)) -> 230V 1ph | S28: =IF($H28="","",VLOOKUP($H28,'Indoor Data'!$B$6:$O$57,10,FALSE)) -> 1.8 | T28: =IF($H28="","",VLOOKUP($H28,'Indoor Data'!$B$6:$O$57,11,FALSE)) -> 1,000 x 300 x 700 | U28: =IF($H28="","",VLOOKUP($H28,'Indoor Data'!$B$6:$O$57,12,FALSE)) -> 35
C29: FF-02 | D29: SHOW KITCHEN / DINING | E29: 12.5 | F29: 10.4 | G29: 765 | H29: FXMQ140PBV1 | I29: =IF($H29="","",VLOOKUP($H29,'Indoor Data'!$B$6:$O$57,13,FALSE)) -> 140 | J29: =IF($H29="","",VLOOKUP($H29,'Indoor Data'!$B$6:$O$57,14,FALSE)) -> India | K29: =IF($H29="","",VLOOKUP($H29,'Indoor Data'!$B$6:$O$57,2,FALSE)) -> Ducted | L29: =IF($H29="","",VLOOKUP($H29,'Indoor Data'!$B$6:$O$57,3,FALSE)) -> 46 - 24.4/17.2 | M29: =IF($H29="","",VLOOKUP($H29,'Indoor Data'!$B$6:$O$57,4,FALSE)) -> 14.2 | N29: =IF($H29="","",VLOOKUP($H29,'Indoor Data'!$B$6:$O$57,5,FALSE)) -> 10.9 | O29: =IF($H29="","",VLOOKUP($H29,'Indoor Data'!$B$6:$O$57,6,FALSE)) -> 766.67 | P29: =IF($H29="","",VLOOKUP($H29,'Indoor Data'!$B$6:$O$57,7,FALSE)) -> 0.405 | Q29: =IF($H29="","",VLOOKUP($H29,'Indoor Data'!$B$6:$O$57,8,FALSE)) -> 43 - 46 | R29: =IF($H29="","",VLOOKUP($H29,'Indoor Data'!$B$6:$O$57,9,FALSE)) -> 230V 1ph | S29: =IF($H29="","",VLOOKUP($H29,'Indoor Data'!$B$6:$O$57,10,FALSE)) -> 3.4 | T29: =IF($H29="","",VLOOKUP($H29,'Indoor Data'!$B$6:$O$57,11,FALSE)) -> 1,400 x 300 x 700 | U29: =IF($H29="","",VLOOKUP($H29,'Indoor Data'!$B$6:$O$57,12,FALSE)) -> 46 | X29: =IF($W29="",0,VLOOKUP($W29,'Outdoor Data'!$B$6:$L$16,11,FALSE)) -> 0 | Y29: =IF($W29="","",VLOOKUP($W29,'Outdoor Data'!$B$6:$L$16,2,FALSE)) | Z29: =IF($W29="","",VLOOKUP($W29,'Outdoor Data'!$B$6:$L$16,3,FALSE)) | AA29: =IF(W29="","",I43/X43) | AB29: =IF($W29="","",VLOOKUP($W29,'Outdoor Data'!$B$6:$L$16,4,FALSE)) | AC29: =IF($W29="","",VLOOKUP($W29,'Outdoor Data'!$B$6:$L$16,5,FALSE)) | AD29: =IF($W29="","",VLOOKUP($W29,'Outdoor Data'!$B$6:$L$16,6,FALSE)) | AE29: =IF($W29="","",VLOOKUP($W29,'Outdoor Data'!$B$6:$L$16,7,FALSE)) | AF29: =IF($W29="","",VLOOKUP($W29,'Outdoor Data'!$B$6:$L$16,8,FALSE)) | AG29: =IF($W29="","",VLOOKUP($W29,'Outdoor Data'!$B$6:$L$16,9,FALSE)) | AH29: =IF($W29="","",VLOOKUP($W29,'Outdoor Data'!$B$6:$L$16,10,FALSE))
C30: FF-03 | D30: SITTING AREA A | E30: 4.6 | F30: 3.5 | G30: 221 | H30: FXMQ50PBV1 | I30: =IF($H30="","",VLOOKUP($H30,'Indoor Data'!$B$6:$O$57,13,FALSE)) -> 50 | J30: =IF($H30="","",VLOOKUP($H30,'Indoor Data'!$B$6:$O$57,14,FALSE)) -> India | K30: =IF($H30="","",VLOOKUP($H30,'Indoor Data'!$B$6:$O$57,2,FALSE)) -> Ducted | L30: =IF($H30="","",VLOOKUP($H30,'Indoor Data'!$B$6:$O$57,3,FALSE)) -> 46 - 24.4/17.2 | M30: =IF($H30="","",VLOOKUP($H30,'Indoor Data'!$B$6:$O$57,4,FALSE)) -> 4.9 | N30: =IF($H30="","",VLOOKUP($H30,'Indoor Data'!$B$6:$O$57,5,FALSE)) -> 4.2 | O30: =IF($H30="","",VLOOKUP($H30,'Indoor Data'!$B$6:$O$57,6,FALSE)) -> 300 | P30: =IF($H30="","",VLOOKUP($H30,'Indoor Data'!$B$6:$O$57,7,FALSE)) -> 0.128 | Q30: =IF($H30="","",VLOOKUP($H30,'Indoor Data'!$B$6:$O$57,8,FALSE)) -> 37 - 41 | R30: =IF($H30="","",VLOOKUP($H30,'Indoor Data'!$B$6:$O$57,9,FALSE)) -> 230V 1ph | S30: =IF($H30="","",VLOOKUP($H30,'Indoor Data'!$B$6:$O$57,10,FALSE)) -> 1.6 | T30: =IF($H30="","",VLOOKUP($H30,'Indoor Data'!$B$6:$O$57,11,FALSE)) -> 1,000 x 300 x 700 | U30: =IF($H30="","",VLOOKUP($H30,'Indoor Data'!$B$6:$O$57,12,FALSE)) -> 35 | V30: VRV-FF | W30: RXQ20ANRYFK | Y30: 46 | Z30: 43.9 | AA30: =IF(W31="","",I43/X43) -> 1.026 | AJ30: Expected CR | AK30: 1.1
C31: FF-04 | D31: SITTING AREA B | E31: 14.5 | F31: 11.7 | G31: 804 | H31: FXMQ170NVE6 | I31: =IF($H31="","",VLOOKUP($H31,'Indoor Data'!$B$6:$O$57,13,FALSE)) -> 170 | J31: =IF($H31="","",VLOOKUP($H31,'Indoor Data'!$B$6:$O$57,14,FALSE)) -> India | K31: =IF($H31="","",VLOOKUP($H31,'Indoor Data'!$B$6:$O$57,2,FALSE)) -> Ducted | L31: =IF($H31="","",VLOOKUP($H31,'Indoor Data'!$B$6:$O$57,3,FALSE)) -> 46 - 24.4/17.2 | M31: =IF($H31="","",VLOOKUP($H31,'Indoor Data'!$B$6:$O$57,4,FALSE)) -> 17.1 | N31: =IF($H31="","",VLOOKUP($H31,'Indoor Data'!$B$6:$O$57,5,FALSE)) -> 13.9 | O31: =IF($H31="","",VLOOKUP($H31,'Indoor Data'!$B$6:$O$57,6,FALSE)) -> 966.67 | P31: =IF($H31="","",VLOOKUP($H31,'Indoor Data'!$B$6:$O$57,7,FALSE)) -> 0.9 | Q31: =IF($H31="","",VLOOKUP($H31,'Indoor Data'!$B$6:$O$57,8,FALSE)) -> 42 - 45 | R31: =IF($H31="","",VLOOKUP($H31,'Indoor Data'!$B$6:$O$57,9,FALSE)) -> 220V 1ph | S31: =IF($H31="","",VLOOKUP($H31,'Indoor Data'!$B$6:$O$57,10,FALSE)) -> 4.9 | T31: =IF($H31="","",VLOOKUP($H31,'Indoor Data'!$B$6:$O$57,11,FALSE)) -> 1,190 x 440 x 1,090 | U31: =IF($H31="","",VLOOKUP($H31,'Indoor Data'!$B$6:$O$57,12,FALSE)) -> 110 | V31: A | W31: RXQ12ARYFK | X31: =IF($W31="",0,VLOOKUP($W31,'Outdoor Data'!$B$6:$L$16,11,FALSE)) -> 300 | AB31: =IF($W31="","",VLOOKUP($W31,'Outdoor Data'!$B$6:$L$16,4,FALSE)) -> 10.4 | AC31: =IF($W31="","",VLOOKUP($W31,'Outdoor Data'!$B$6:$L$16,5,FALSE)) -> 400V 3Nph | AD31: =IF($W31="","",VLOOKUP($W31,'Outdoor Data'!$B$6:$L$16,6,FALSE)) -> 26.9 | AE31: =IF($W31="","",VLOOKUP($W31,'Outdoor Data'!$B$6:$L$16,7,FALSE)) -> - | AF31: =IF($W31="","",VLOOKUP($W31,'Outdoor Data'!$B$6:$L$16,8,FALSE)) -> - | AG31: =IF($W31="","",VLOOKUP($W31,'Outdoor Data'!$B$6:$L$16,9,FALSE)) -> 1,240 x 1,657 x 765 | AH31: =IF($W31="","",VLOOKUP($W31,'Outdoor Data'!$B$6:$L$16,10,FALSE)) -> 220 | AJ31: Required ODU | AK31: =(I43/AK30)/25 -> 18.654545 | AL31: hp
C32: FF-05 | D32: MASSAGE / SALOON | E32: 4.5 | F32: 3.6 | G32: 246 | H32: FXMQ50PBV1 | I32: =IF($H32="","",VLOOKUP($H32,'Indoor Data'!$B$6:$O$57,13,FALSE)) -> 50 | J32: =IF($H32="","",VLOOKUP($H32,'Indoor Data'!$B$6:$O$57,14,FALSE)) -> India | K32: =IF($H32="","",VLOOKUP($H32,'Indoor Data'!$B$6:$O$57,2,FALSE)) -> Ducted | L32: =IF($H32="","",VLOOKUP($H32,'Indoor Data'!$B$6:$O$57,3,FALSE)) -> 46 - 24.4/17.2 | M32: =IF($H32="","",VLOOKUP($H32,'Indoor Data'!$B$6:$O$57,4,FALSE)) -> 4.9 | N32: =IF($H32="","",VLOOKUP($H32,'Indoor Data'!$B$6:$O$57,5,FALSE)) -> 4.2 | O32: =IF($H32="","",VLOOKUP($H32,'Indoor Data'!$B$6:$O$57,6,FALSE)) -> 300 | P32: =IF($H32="","",VLOOKUP($H32,'Indoor Data'!$B$6:$O$57,7,FALSE)) -> 0.128 | Q32: =IF($H32="","",VLOOKUP($H32,'Indoor Data'!$B$6:$O$57,8,FALSE)) -> 37 - 41 | R32: =IF($H32="","",VLOOKUP($H32,'Indoor Data'!$B$6:$O$57,9,FALSE)) -> 230V 1ph | S32: =IF($H32="","",VLOOKUP($H32,'Indoor Data'!$B$6:$O$57,10,FALSE)) -> 1.6 | T32: =IF($H32="","",VLOOKUP($H32,'Indoor Data'!$B$6:$O$57,11,FALSE)) -> 1,000 x 300 x 700 | U32: =IF($H32="","",VLOOKUP($H32,'Indoor Data'!$B$6:$O$57,12,FALSE)) -> 35 | V32: B | W32: RXQ8ARYFK | X32: =IF($W32="",0,VLOOKUP($W32,'Outdoor Data'!$B$6:$L$16,11,FALSE)) -> 200 | AB32: =IF($W32="","",VLOOKUP($W32,'Outdoor Data'!$B$6:$L$16,4,FALSE)) -> 6.5 | AC32: =IF($W32="","",VLOOKUP($W32,'Outdoor Data'!$B$6:$L$16,5,FALSE)) -> 400V 3Nph | AD32: =IF($W32="","",VLOOKUP($W32,'Outdoor Data'!$B$6:$L$16,6,FALSE)) -> 21.2 | AE32: =IF($W32="","",VLOOKUP($W32,'Outdoor Data'!$B$6:$L$16,7,FALSE)) -> - | AF32: =IF($W32="","",VLOOKUP($W32,'Outdoor Data'!$B$6:$L$16,8,FALSE)) -> - | AG32: =IF($W32="","",VLOOKUP($W32,'Outdoor Data'!$B$6:$L$16,9,FALSE)) -> 930 x 1,657 x 765 | AH32: =IF($W32="","",VLOOKUP($W32,'Outdoor Data'!$B$6:$L$16,10,FALSE)) -> 175
C33: FF-06 | D33: LOBBY / LINEN AREA | E33: 3.2 | F33: 2.4 | G33: 151 | H33: FXMQ40PBV1 | I33: =IF($H33="","",VLOOKUP($H33,'Indoor Data'!$B$6:$O$57,13,FALSE)) -> 40 | J33: =IF($H33="","",VLOOKUP($H33,'Indoor Data'!$B$6:$O$57,14,FALSE)) -> India | K33: =IF($H33="","",VLOOKUP($H33,'Indoor Data'!$B$6:$O$57,2,FALSE)) -> Ducted | L33: =IF($H33="","",VLOOKUP($H33,'Indoor Data'!$B$6:$O$57,3,FALSE)) -> 46 - 24.4/17.2 | M33: =IF($H33="","",VLOOKUP($H33,'Indoor Data'!$B$6:$O$57,4,FALSE)) -> 4 | N33: =IF($H33="","",VLOOKUP($H33,'Indoor Data'!$B$6:$O$57,5,FALSE)) -> 3.5 | O33: =IF($H33="","",VLOOKUP($H33,'Indoor Data'!$B$6:$O$57,6,FALSE)) -> 266.67 | P33: =IF($H33="","",VLOOKUP($H33,'Indoor Data'!$B$6:$O$57,7,FALSE)) -> 0.151 | Q33: =IF($H33="","",VLOOKUP($H33,'Indoor Data'!$B$6:$O$57,8,FALSE)) -> 35 - 39 | R33: =IF($H33="","",VLOOKUP($H33,'Indoor Data'!$B$6:$O$57,9,FALSE)) -> 230V 1ph | S33: =IF($H33="","",VLOOKUP($H33,'Indoor Data'!$B$6:$O$57,10,FALSE)) -> 1.4 | T33: =IF($H33="","",VLOOKUP($H33,'Indoor Data'!$B$6:$O$57,11,FALSE)) -> 700 x 300 x 700 | U33: =IF($H33="","",VLOOKUP($H33,'Indoor Data'!$B$6:$O$57,12,FALSE)) -> 27 | X33: =IF($W33="",0,VLOOKUP($W33,'Outdoor Data'!$B$6:$L$16,11,FALSE)) -> 0 | Y33: =IF($W33="","",VLOOKUP($W33,'Outdoor Data'!$B$6:$L$16,2,FALSE)) | Z33: =IF($W33="","",VLOOKUP($W33,'Outdoor Data'!$B$6:$L$16,3,FALSE)) | AB33: =IF($W33="","",VLOOKUP($W33,'Outdoor Data'!$B$6:$L$16,4,FALSE)) | AC33: =IF($W33="","",VLOOKUP($W33,'Outdoor Data'!$B$6:$L$16,5,FALSE)) | AD33: =IF($W33="","",VLOOKUP($W33,'Outdoor Data'!$B$6:$L$16,6,FALSE)) | AE33: =IF($W33="","",VLOOKUP($W33,'Outdoor Data'!$B$6:$L$16,7,FALSE)) | AF33: =IF($W33="","",VLOOKUP($W33,'Outdoor Data'!$B$6:$L$16,8,FALSE)) | AG33: =IF($W33="","",VLOOKUP($W33,'Outdoor Data'!$B$6:$L$16,9,FALSE)) | AH33: =IF($W33="","",VLOOKUP($W33,'Outdoor Data'!$B$6:$L$16,10,FALSE))
I34: =IF($H34="","",VLOOKUP($H34,'Indoor Data'!$B$6:$O$57,13,FALSE)) | J34: =IF($H34="","",VLOOKUP($H34,'Indoor Data'!$B$6:$O$57,14,FALSE)) | K34: =IF($H34="","",VLOOKUP($H34,'Indoor Data'!$B$6:$O$57,2,FALSE)) | L34: =IF($H34="","",VLOOKUP($H34,'Indoor Data'!$B$6:$O$57,3,FALSE)) | M34: =IF($H34="","",VLOOKUP($H34,'Indoor Data'!$B$6:$O$57,4,FALSE)) | N34: =IF($H34="","",VLOOKUP($H34,'Indoor Data'!$B$6:$O$57,5,FALSE)) | O34: =IF($H34="","",VLOOKUP($H34,'Indoor Data'!$B$6:$O$57,6,FALSE)) | P34: =IF($H34="","",VLOOKUP($H34,'Indoor Data'!$B$6:$O$57,7,FALSE)) | Q34: =IF($H34="","",VLOOKUP($H34,'Indoor Data'!$B$6:$O$57,8,FALSE)) | R34: =IF($H34="","",VLOOKUP($H34,'Indoor Data'!$B$6:$O$57,9,FALSE)) | S34: =IF($H34="","",VLOOKUP($H34,'Indoor Data'!$B$6:$O$57,10,FALSE)) | T34: =IF($H34="","",VLOOKUP($H34,'Indoor Data'!$B$6:$O$57,11,FALSE)) | U34: =IF($H34="","",VLOOKUP($H34,'Indoor Data'!$B$6:$O$57,12,FALSE))
I35: =IF($H35="","",VLOOKUP($H35,'Indoor Data'!$B$6:$O$57,13,FALSE)) | J35: =IF($H35="","",VLOOKUP($H35,'Indoor Data'!$B$6:$O$57,14,FALSE)) | K35: =IF($H35="","",VLOOKUP($H35,'Indoor Data'!$B$6:$O$57,2,FALSE)) | L35: =IF($H35="","",VLOOKUP($H35,'Indoor Data'!$B$6:$O$57,3,FALSE)) | M35: =IF($H35="","",VLOOKUP($H35,'Indoor Data'!$B$6:$O$57,4,FALSE)) | N35: =IF($H35="","",VLOOKUP($H35,'Indoor Data'!$B$6:$O$57,5,FALSE)) | O35: =IF($H35="","",VLOOKUP($H35,'Indoor Data'!$B$6:$O$57,6,FALSE)) | P35: =IF($H35="","",VLOOKUP($H35,'Indoor Data'!$B$6:$O$57,7,FALSE)) | Q35: =IF($H35="","",VLOOKUP($H35,'Indoor Data'!$B$6:$O$57,8,FALSE)) | R35: =IF($H35="","",VLOOKUP($H35,'Indoor Data'!$B$6:$O$57,9,FALSE)) | S35: =IF($H35="","",VLOOKUP($H35,'Indoor Data'!$B$6:$O$57,10,FALSE)) | T35: =IF($H35="","",VLOOKUP($H35,'Indoor Data'!$B$6:$O$57,11,FALSE)) | U35: =IF($H35="","",VLOOKUP($H35,'Indoor Data'!$B$6:$O$57,12,FALSE))
I36: =IF($H36="","",VLOOKUP($H36,'Indoor Data'!$B$6:$O$57,13,FALSE)) | J36: =IF($H36="","",VLOOKUP($H36,'Indoor Data'!$B$6:$O$57,14,FALSE)) | K36: =IF($H36="","",VLOOKUP($H36,'Indoor Data'!$B$6:$O$57,2,FALSE)) | L36: =IF($H36="","",VLOOKUP($H36,'Indoor Data'!$B$6:$O$57,3,FALSE)) | M36: =IF($H36="","",VLOOKUP($H36,'Indoor Data'!$B$6:$O$57,4,FALSE)) | N36: =IF($H36="","",VLOOKUP($H36,'Indoor Data'!$B$6:$O$57,5,FALSE)) | O36: =IF($H36="","",VLOOKUP($H36,'Indoor Data'!$B$6:$O$57,6,FALSE)) | P36: =IF($H36="","",VLOOKUP($H36,'Indoor Data'!$B$6:$O$57,7,FALSE)) | Q36: =IF($H36="","",VLOOKUP($H36,'Indoor Data'!$B$6:$O$57,8,FALSE)) | R36: =IF($H36="","",VLOOKUP($H36,'Indoor Data'!$B$6:$O$57,9,FALSE)) | S36: =IF($H36="","",VLOOKUP($H36,'Indoor Data'!$B$6:$O$57,10,FALSE)) | T36: =IF($H36="","",VLOOKUP($H36,'Indoor Data'!$B$6:$O$57,11,FALSE)) | U36: =IF($H36="","",VLOOKUP($H36,'Indoor Data'!$B$6:$O$57,12,FALSE))
I37: =IF($H37="","",VLOOKUP($H37,'Indoor Data'!$B$6:$O$57,13,FALSE)) | J37: =IF($H37="","",VLOOKUP($H37,'Indoor Data'!$B$6:$O$57,14,FALSE)) | K37: =IF($H37="","",VLOOKUP($H37,'Indoor Data'!$B$6:$O$57,2,FALSE)) | L37: =IF($H37="","",VLOOKUP($H37,'Indoor Data'!$B$6:$O$57,3,FALSE)) | M37: =IF($H37="","",VLOOKUP($H37,'Indoor Data'!$B$6:$O$57,4,FALSE)) | N37: =IF($H37="","",VLOOKUP($H37,'Indoor Data'!$B$6:$O$57,5,FALSE)) | O37: =IF($H37="","",VLOOKUP($H37,'Indoor Data'!$B$6:$O$57,6,FALSE)) | P37: =IF($H37="","",VLOOKUP($H37,'Indoor Data'!$B$6:$O$57,7,FALSE)) | Q37: =IF($H37="","",VLOOKUP($H37,'Indoor Data'!$B$6:$O$57,8,FALSE)) | R37: =IF($H37="","",VLOOKUP($H37,'Indoor Data'!$B$6:$O$57,9,FALSE)) | S37: =IF($H37="","",VLOOKUP($H37,'Indoor Data'!$B$6:$O$57,10,FALSE)) | T37: =IF($H37="","",VLOOKUP($H37,'Indoor Data'!$B$6:$O$57,11,FALSE)) | U37: =IF($H37="","",VLOOKUP($H37,'Indoor Data'!$B$6:$O$57,12,FALSE))
I38: =IF($H38="","",VLOOKUP($H38,'Indoor Data'!$B$6:$O$57,13,FALSE)) | J38: =IF($H38="","",VLOOKUP($H38,'Indoor Data'!$B$6:$O$57,14,FALSE)) | K38: =IF($H38="","",VLOOKUP($H38,'Indoor Data'!$B$6:$O$57,2,FALSE)) | L38: =IF($H38="","",VLOOKUP($H38,'Indoor Data'!$B$6:$O$57,3,FALSE)) | M38: =IF($H38="","",VLOOKUP($H38,'Indoor Data'!$B$6:$O$57,4,FALSE)) | N38: =IF($H38="","",VLOOKUP($H38,'Indoor Data'!$B$6:$O$57,5,FALSE)) | O38: =IF($H38="","",VLOOKUP($H38,'Indoor Data'!$B$6:$O$57,6,FALSE)) | P38: =IF($H38="","",VLOOKUP($H38,'Indoor Data'!$B$6:$O$57,7,FALSE)) | Q38: =IF($H38="","",VLOOKUP($H38,'Indoor Data'!$B$6:$O$57,8,FALSE)) | R38: =IF($H38="","",VLOOKUP($H38,'Indoor Data'!$B$6:$O$57,9,FALSE)) | S38: =IF($H38="","",VLOOKUP($H38,'Indoor Data'!$B$6:$O$57,10,FALSE)) | T38: =IF($H38="","",VLOOKUP($H38,'Indoor Data'!$B$6:$O$57,11,FALSE)) | U38: =IF($H38="","",VLOOKUP($H38,'Indoor Data'!$B$6:$O$57,12,FALSE))
I39: =IF($H39="","",VLOOKUP($H39,'Indoor Data'!$B$6:$O$57,13,FALSE)) | J39: =IF($H39="","",VLOOKUP($H39,'Indoor Data'!$B$6:$O$57,14,FALSE)) | K39: =IF($H39="","",VLOOKUP($H39,'Indoor Data'!$B$6:$O$57,2,FALSE)) | L39: =IF($H39="","",VLOOKUP($H39,'Indoor Data'!$B$6:$O$57,3,FALSE)) | M39: =IF($H39="","",VLOOKUP($H39,'Indoor Data'!$B$6:$O$57,4,FALSE)) | N39: =IF($H39="","",VLOOKUP($H39,'Indoor Data'!$B$6:$O$57,5,FALSE)) | O39: =IF($H39="","",VLOOKUP($H39,'Indoor Data'!$B$6:$O$57,6,FALSE)) | P39: =IF($H39="","",VLOOKUP($H39,'Indoor Data'!$B$6:$O$57,7,FALSE)) | Q39: =IF($H39="","",VLOOKUP($H39,'Indoor Data'!$B$6:$O$57,8,FALSE)) | R39: =IF($H39="","",VLOOKUP($H39,'Indoor Data'!$B$6:$O$57,9,FALSE)) | S39: =IF($H39="","",VLOOKUP($H39,'Indoor Data'!$B$6:$O$57,10,FALSE)) | T39: =IF($H39="","",VLOOKUP($H39,'Indoor Data'!$B$6:$O$57,11,FALSE)) | U39: =IF($H39="","",VLOOKUP($H39,'Indoor Data'!$B$6:$O$57,12,FALSE))
I40: =IF($H40="","",VLOOKUP($H40,'Indoor Data'!$B$6:$O$57,13,FALSE)) | J40: =IF($H40="","",VLOOKUP($H40,'Indoor Data'!$B$6:$O$57,14,FALSE)) | K40: =IF($H40="","",VLOOKUP($H40,'Indoor Data'!$B$6:$O$57,2,FALSE)) | L40: =IF($H40="","",VLOOKUP($H40,'Indoor Data'!$B$6:$O$57,3,FALSE)) | M40: =IF($H40="","",VLOOKUP($H40,'Indoor Data'!$B$6:$O$57,4,FALSE)) | N40: =IF($H40="","",VLOOKUP($H40,'Indoor Data'!$B$6:$O$57,5,FALSE)) | O40: =IF($H40="","",VLOOKUP($H40,'Indoor Data'!$B$6:$O$57,6,FALSE)) | P40: =IF($H40="","",VLOOKUP($H40,'Indoor Data'!$B$6:$O$57,7,FALSE)) | Q40: =IF($H40="","",VLOOKUP($H40,'Indoor Data'!$B$6:$O$57,8,FALSE)) | R40: =IF($H40="","",VLOOKUP($H40,'Indoor Data'!$B$6:$O$57,9,FALSE)) | S40: =IF($H40="","",VLOOKUP($H40,'Indoor Data'!$B$6:$O$57,10,FALSE)) | T40: =IF($H40="","",VLOOKUP($H40,'Indoor Data'!$B$6:$O$57,11,FALSE)) | U40: =IF($H40="","",VLOOKUP($H40,'Indoor Data'!$B$6:$O$57,12,FALSE))
I41: =IF($H41="","",VLOOKUP($H41,'Indoor Data'!$B$6:$O$57,13,FALSE)) | J41: =IF($H41="","",VLOOKUP($H41,'Indoor Data'!$B$6:$O$57,14,FALSE)) | K41: =IF($H41="","",VLOOKUP($H41,'Indoor Data'!$B$6:$O$57,2,FALSE)) | L41: =IF($H41="","",VLOOKUP($H41,'Indoor Data'!$B$6:$O$57,3,FALSE)) | M41: =IF($H41="","",VLOOKUP($H41,'Indoor Data'!$B$6:$O$57,4,FALSE)) | N41: =IF($H41="","",VLOOKUP($H41,'Indoor Data'!$B$6:$O$57,5,FALSE)) | O41: =IF($H41="","",VLOOKUP($H41,'Indoor Data'!$B$6:$O$57,6,FALSE)) | P41: =IF($H41="","",VLOOKUP($H41,'Indoor Data'!$B$6:$O$57,7,FALSE)) | Q41: =IF($H41="","",VLOOKUP($H41,'Indoor Data'!$B$6:$O$57,8,FALSE)) | R41: =IF($H41="","",VLOOKUP($H41,'Indoor Data'!$B$6:$O$57,9,FALSE)) | S41: =IF($H41="","",VLOOKUP($H41,'Indoor Data'!$B$6:$O$57,10,FALSE)) | T41: =IF($H41="","",VLOOKUP($H41,'Indoor Data'!$B$6:$O$57,11,FALSE)) | U41: =IF($H41="","",VLOOKUP($H41,'Indoor Data'!$B$6:$O$57,12,FALSE))
I42: =IF($H42="","",VLOOKUP($H42,'Indoor Data'!$B$6:$O$57,13,FALSE)) | J42: =IF($H42="","",VLOOKUP($H42,'Indoor Data'!$B$6:$O$57,14,FALSE)) | K42: =IF($H42="","",VLOOKUP($H42,'Indoor Data'!$B$6:$O$57,2,FALSE)) | L42: =IF($H42="","",VLOOKUP($H42,'Indoor Data'!$B$6:$O$57,3,FALSE)) | M42: =IF($H42="","",VLOOKUP($H42,'Indoor Data'!$B$6:$O$57,4,FALSE)) | N42: =IF($H42="","",VLOOKUP($H42,'Indoor Data'!$B$6:$O$57,5,FALSE)) | O42: =IF($H42="","",VLOOKUP($H42,'Indoor Data'!$B$6:$O$57,6,FALSE)) | P42: =IF($H42="","",VLOOKUP($H42,'Indoor Data'!$B$6:$O$57,7,FALSE)) | Q42: =IF($H42="","",VLOOKUP($H42,'Indoor Data'!$B$6:$O$57,8,FALSE)) | R42: =IF($H42="","",VLOOKUP($H42,'Indoor Data'!$B$6:$O$57,9,FALSE)) | S42: =IF($H42="","",VLOOKUP($H42,'Indoor Data'!$B$6:$O$57,10,FALSE)) | T42: =IF($H42="","",VLOOKUP($H42,'Indoor Data'!$B$6:$O$57,11,FALSE)) | U42: =IF($H42="","",VLOOKUP($H42,'Indoor Data'!$B$6:$O$57,12,FALSE))
E43: =SUM(E28:E42) -> 44.3 | F43: =SUM(F28:F42) -> 35.4 | G43: =SUM(G28:G42) -> 2436 | I43: =SUM(I28:I42) -> 513 | M43: =SUM(M28:M42) -> 51.3 | N43: =SUM(N28:N42) -> 41.8 | O43: =SUM(O28:O42) -> 2925.01 | P43: =SUM(P28:P42) -> 1.85 | X43: =X33+X32+X31+X29 -> 500 | AB43: =SUM(AB28:AB42) -> 16.9
B45: VRV-SF | C45: SF-01 | D45: MASTER BEDROOM | E45: 9.9 | F45: 8.5 | G45: 630 | H45: FXMQ125PBV1 | I45: =IF($H45="","",VLOOKUP($H45,'Indoor Data'!$B$6:$O$57,13,FALSE)) -> 125 | J45: =IF($H45="","",VLOOKUP($H45,'Indoor Data'!$B$6:$O$57,14,FALSE)) -> India | K45: =IF($H45="","",VLOOKUP($H45,'Indoor Data'!$B$6:$O$57,2,FALSE)) -> Ducted | L45: =IF($H45="","",VLOOKUP($H45,'Indoor Data'!$B$6:$O$57,3,FALSE)) -> 46 - 24.4/17.2 | M45: =IF($H45="","",VLOOKUP($H45,'Indoor Data'!$B$6:$O$57,4,FALSE)) -> 12.4 | N45: =IF($H45="","",VLOOKUP($H45,'Indoor Data'!$B$6:$O$57,5,FALSE)) -> 9.6 | O45: =IF($H45="","",VLOOKUP($H45,'Indoor Data'!$B$6:$O$57,6,FALSE)) -> 650 | P45: =IF($H45="","",VLOOKUP($H45,'Indoor Data'!$B$6:$O$57,7,FALSE)) -> 0.284 | Q45: =IF($H45="","",VLOOKUP($H45,'Indoor Data'!$B$6:$O$57,8,FALSE)) -> 40 - 44 | R45: =IF($H45="","",VLOOKUP($H45,'Indoor Data'!$B$6:$O$57,9,FALSE)) -> 230V 1ph | S45: =IF($H45="","",VLOOKUP($H45,'Indoor Data'!$B$6:$O$57,10,FALSE)) -> 3.4 | T45: =IF($H45="","",VLOOKUP($H45,'Indoor Data'!$B$6:$O$57,11,FALSE)) -> 1,400 x 300 x 700 | U45: =IF($H45="","",VLOOKUP($H45,'Indoor Data'!$B$6:$O$57,12,FALSE)) -> 45
...

Sheet Indoor Data
B2: 1 | C2: 2 | D2: 3 | E2: 4 | F2: 5 | G2: 6 | H2: 7 | I2: 8 | J2: 9 | K2: 10 | L2: 11 | M2: 12 | N2: 13 | O2: 14
B3: FCU | C3: Type | D3: Ambient - On Coil Temperature | E3: Max TC | F3: Max SC | G3: Air Flow Rate | H3: PIC | I3: Sound | J3: PS | K3: MCA | L3: WxHxD | M3: Weight | N3: Nominal Index | O3: Country of Origin
D4: °C | E4: kW | F4: kW | G4: l/s | H4: kW | I4: dBA | K4: A | L4: mm | M4: kg
D5: (DBT/WBT)
B6: FXSQ15A | C6: Ducted | D6: 46 - 24.4/17.2 | E6: 1.5 | F6: 1.1 | G6: 145 | H6: 0.041 | I6: 25 - 30 | J6: 220V 1ph | K6: 0.8 | L6: 550 x 245 x 800 | M6: 23.5 | N6: 15 | O6: Czech Republic
B7: FXSQ20A | C7: Ducted | D7: 46 - 24.4/17.2 | E7: 2 | F7: 1.5 | G7: 150 | H7: 0.041 | I7: 25 - 30 | J7: 220V 1ph | K7: 0.8 | L7: 550 x 245 x 800 | M7: 23.5 | N7: 20 | O7: Czech Republic
B8: FXSQ25A | C8: Ducted | D8: 46 - 24.4/17.2 | E8: 2.5 | F8: 1.9 | G8: 150 | H8: 0.041 | I8: 25 - 30 | J8: 220V 1ph | K8: 0.8 | L8: 550 x 245 x 800 | M8: 23.5 | N8: 25 | O8: Czech Republic
B9: FXSQ32A | C9: Ducted | D9: 46 - 24.4/17.2 | E9: 3.2 | F9: 2.4 | G9: 158.33 | H9: 0.045 | I9: 26 - 26 | J9: 220V 1ph | K9: 0.8 | L9: 550 x 245 x 800 | M9: 24 | N9: 32 | O9: Czech Republic
B10: FXSQ40A | C10: Ducted | D10: 46 - 24.4/17.2 | E10: 4 | F10: 3.1 | G10: 250 | H10: 0.087 | I10: 29 - 35 | J10: 220V 1ph | K10: 1.1 | L10: 700 x 245 x 800 | M10: 28.5 | N10: 40 | O10: Czech Republic
B11: FXSQ50A | C11: Ducted | D11: 46 - 24.4/17.2 | E11: 4.9 | F11: 3.7 | G11: 253.33 | H11: 0.089 | I11: 29 - 35 | J11: 220V 1ph | K11: 1.1 | L11: 700 x 245 x 800 | M11: 29 | N11: 50 | O11: Czech Republic
B12: FXSQ63A | C12: Ducted | D12: 46 - 24.4/17.2 | E12: 6.2 | F12: 4.7 | G12: 350 | H12: 0.101 | I12: 27 - 33 | J12: 220V 1ph | K12: 1.6 | L12: 1,000 x 245 x 800 | M12: 35.5 | N12: 63 | O12: Czech Republic
B13: FXSQ80A | C13: Ducted | D13: 46 - 24.4/17.2 | E13: 7.9 | F13: 5.9 | G13: 383.33 | H13: 0.135 | I13: 29 - 35 | J13: 220V 1ph | K13: 1.9 | L13: 1,000 x 245 x 800 | M13: 36.5 | N13: 80 | O13: Czech Republic
B14: FXSQ100A | C14: Ducted | D14: 46 - 24.4/17.2 | E14: 9.9 | F14: 7.5 | G14: 533.33 | H14: 0.173 | I14: 31 - 36 | J14: 220V 1ph | K14: 2.4 | L14: 1,400 x 245 x 800 | M14: 46 | N14: 100 | O14: Czech Republic
B15: FXSQ125A | C15: Ducted | D15: 46 - 24.4/17.2 | E15: 12.4 | F15: 9.3 | G15: 600 | H15: 0.237 | I15: 33 - 39 | J15: 220V 1ph | K15: 2.6 | L15: 1,400 x 245 x 800 | M15: 47 | N15: 125 | O15: Czech Republic
B16: FXSQ140A | C16: Ducted | D16: 46 - 24.4/17.2 | E16: 14.2 | F16: 10.6 | G16: 650 | H16: 0.247 | I16: 34 - 42 | J16: 220V 1ph | K16: 3.1 | L16: 1,550 x 245 x 800 | M16: 51 | N16: 140 | O16: Czech Republic
B17: FXMQ40PBV1 | C17: Ducted | D17: 46 - 24.4/17.2 | E17: 4 | F17: 3.5 | G17: 266.67 | H17: 0.151 | I17: 35 - 39 | J17: 230V 1ph | K17: 1.4 | L17: 700 x 300 x 700 | M17: 27 | N17: 40 | O17: India
... B57: FXFSQ140ARV1 | C57: Cassette | D57: 46 - 24.4/17.2 | E57: 14.2 | F57: 10.6 | G57: 591.67 | H57: 0.194 | I57: 35 - 46 | J57: 230V 1ph | K57: 1.8 | L57: 840 x 298 x 840 | M57: 26 | N57: 140 | O57: India

Sheet Outdoor Data
B2: 1 | C2: 2 | D2: 3 | E2: 4 | F2: 5 | G2: 6 | H2: 7 | I2: 8 | J2: 9 | K2: 10 | L2: 11
B3: Model | C3: Ambient Temp | D3: CC | E3: PI ESMA (Kw) | F3: PS | G3: MCA | H3: MOP | I3: RLA | J3: WxHxD | K3: Weight | L3: Nominal Index
D4: kw | G4: A | H4: A | I4: A | J4: mm | K4: kg
B6: RXQ6ARYFK | C6: 46 | D6: 12.6 | E6: 5.1 | F6: 400V 3Nph | G6: 16.1 | H6: - | I6: - | J6: 930 x 1,657 x 765 | K6: 165 | L6: 150
B7: RXQ8ARYFK | C7: 46 | D7: 17.7 | E7: 6.5 | F7: 400V 3Nph | G7: 21.2 | H7: - | I7: - | J7: 930 x 1,657 x 765 | K7: 175 | L7: 200
B8: RXQ10ARYFK | C8: 46 | D8: 23.9 | E8: 9.4 | F8: 400V 3Nph | G8: 26.9 | H8: - | I8: - | J8: 1,240 x 1,657 x 765 | K8: 220 | L8: 250
B9: RXQ12ARYFK | C9: 46 | D9: 27.1 | E9: 10.4 | F9: 400V 3Nph | G9: 26.9 | H9: - | I9: - | J9: 1,240 x 1,657 x 765 | K9: 220 | L9: 300
B10: RXQ14ARYFK | C10: 46 | D10: 30.3 | E10: 12.5 | F10: 400V 3Nph | G10: 38.9 | H10: - | I10: - | J10: 1,240 x 1,657 x 765 | K10: 285 | L10: 350
B11: RXQ16ARYFK | C11: 46 | D11: 33.3 | E11: 12.5 | F11: 400V 3Nph | G11: 38.9 | H11: - | I11: - | J11: 1,240 x 1,657 x 765 | K11: 285 | L11: 400
B12: RXYTQ8U5YF | C12: 46 | D12: 17.7 | E12: 6.56 | F12: 400V 3Nph | G12: 16.1 | H12: 20 | I12: 8 | J12: 930 x 1,685 x 765 | K12: 198 | L12: 200
B13: RXYTQ10U5YF | C13: 46 | D13: 23.3 | E13: 7.95 | F13: 400V 3Nph | G13: 22 | H13: 25 | I13: 9.3 | J13: 1,240 x 1,685 x 765 | K13: 234 | L13: 250
B14: RXYTQ12U5YF | C14: 46 | D14: 27.1 | E14: 8.72 | F14: 400V 3Nph | G14: 24 | H14: 32 | I14: 12.7 | J14: 1,240 x 1,685 x 765 | K14: 234 | L14: 300
B15: RXYTQ14U5YF | C15: 46 | D15: 30.7 | E15: 10 | F15: 400V 3Nph | G15: 27 | H15: 32 | I15: 15.8 | J15: 1,240 x 1,685 x 765 | K15: 283 | L15: 350
B16: RXYTQ16U5YF | C16: 46 | D16: 33.3 | E16: 12.1 | F16: 400V 3Nph | G16: 31 | H16: 40 | I16: 19.3 | J16: 1,240 x 1,685 x 765 | K16: 283 | L16: 400
